Watching for file changes with StatReloader
C:\Users\kt841\Documents\SocialMedia\social_media\social_media\settings.py changed, reloading.
Watching for file changes with StatReloader
Not Found: /user/signup/
"POST /user/signup/ HTTP/1.1" 404 67
C:\Users\kt841\Documents\SocialMedia\social_media\user_profile\views.py changed, reloading.
Watching for file changes with StatReloader
C:\Users\kt841\Documents\SocialMedia\social_media\user_profile\views.py changed, reloading.
Watching for file changes with StatReloader
C:\Users\kt841\Documents\SocialMedia\social_media\user_profile\views.py changed, reloading.
Watching for file changes with StatReloader
C:\Users\kt841\Documents\SocialMedia\social_media\user_profile\views.py changed, reloading.
Watching for file changes with StatReloader
C:\Users\kt841\Documents\SocialMedia\social_media\user_profile\views.py changed, reloading.
Watching for file changes with StatReloader
Not Found: /user/signup/
"POST /user/signup/ HTTP/1.1" 404 67
C:\Users\kt841\Documents\SocialMedia\social_media\user_profile\views.py changed, reloading.
Watching for file changes with StatReloader
C:\Users\kt841\Documents\SocialMedia\social_media\user_profile\views.py changed, reloading.
Watching for file changes with StatReloader
C:\Users\kt841\Documents\SocialMedia\social_media\user_profile\views.py changed, reloading.
Watching for file changes with StatReloader
Not Found: /user/signup/
"POST /user/signup/ HTTP/1.1" 404 67
Not Found: /user/signup/
"POST /user/signup/ HTTP/1.1" 404 67
C:\Users\kt841\Documents\SocialMedia\social_media\user_profile\views.py changed, reloading.
Watching for file changes with StatReloader
C:\Users\kt841\Documents\SocialMedia\social_media\user_profile\views.py changed, reloading.
Watching for file changes with StatReloader
C:\Users\kt841\Documents\SocialMedia\social_media\post\models.py changed, reloading.
Watching for file changes with StatReloader
C:\Users\kt841\Documents\SocialMedia\social_media\post\models.py changed, reloading.
Watching for file changes with StatReloader
C:\Users\kt841\Documents\SocialMedia\social_media\post\models.py changed, reloading.
Watching for file changes with StatReloader
C:\Users\kt841\Documents\SocialMedia\social_media\post\models.py changed, reloading.
Watching for file changes with StatReloader
C:\Users\kt841\Documents\SocialMedia\social_media\post\models.py changed, reloading.
Watching for file changes with StatReloader
C:\Users\kt841\Documents\SocialMedia\social_media\post\models.py changed, reloading.
Watching for file changes with StatReloader
C:\Users\kt841\Documents\SocialMedia\social_media\post\views.py changed, reloading.
Watching for file changes with StatReloader
C:\Users\kt841\Documents\SocialMedia\social_media\post\views.py changed, reloading.
Watching for file changes with StatReloader
C:\Users\kt841\Documents\SocialMedia\social_media\post\views.py changed, reloading.
Watching for file changes with StatReloader
C:\Users\kt841\Documents\SocialMedia\social_media\post\views.py changed, reloading.
Watching for file changes with StatReloader
C:\Users\kt841\Documents\SocialMedia\social_media\post\views.py changed, reloading.
Watching for file changes with StatReloader
C:\Users\kt841\Documents\SocialMedia\social_media\post\views.py changed, reloading.
Watching for file changes with StatReloader
C:\Users\kt841\Documents\SocialMedia\social_media\post\views.py changed, reloading.
Watching for file changes with StatReloader
C:\Users\kt841\Documents\SocialMedia\social_media\post\views.py changed, reloading.
Watching for file changes with StatReloader
C:\Users\kt841\Documents\SocialMedia\social_media\post\views.py changed, reloading.
Watching for file changes with StatReloader
C:\Users\kt841\Documents\SocialMedia\social_media\post\views.py changed, reloading.
Watching for file changes with StatReloader
C:\Users\kt841\Documents\SocialMedia\social_media\post\views.py changed, reloading.
Watching for file changes with StatReloader
C:\Users\kt841\Documents\SocialMedia\social_media\post\views.py changed, reloading.
Watching for file changes with StatReloader
C:\Users\kt841\Documents\SocialMedia\social_media\post\views.py changed, reloading.
Watching for file changes with StatReloader
C:\Users\kt841\Documents\SocialMedia\social_media\post\views.py changed, reloading.
Watching for file changes with StatReloader
C:\Users\kt841\Documents\SocialMedia\social_media\post\views.py changed, reloading.
Watching for file changes with StatReloader
C:\Users\kt841\Documents\SocialMedia\social_media\post\views.py changed, reloading.
Watching for file changes with StatReloader
C:\Users\kt841\Documents\SocialMedia\social_media\post\views.py changed, reloading.
Watching for file changes with StatReloader
C:\Users\kt841\Documents\SocialMedia\social_media\post\views.py changed, reloading.
Watching for file changes with StatReloader
C:\Users\kt841\Documents\SocialMedia\social_media\post\views.py changed, reloading.
Watching for file changes with StatReloader
C:\Users\kt841\Documents\SocialMedia\social_media\post\views.py changed, reloading.
Watching for file changes with StatReloader
C:\Users\kt841\Documents\SocialMedia\social_media\post\views.py changed, reloading.
Watching for file changes with StatReloader
C:\Users\kt841\Documents\SocialMedia\social_media\post\views.py changed, reloading.
Watching for file changes with StatReloader
C:\Users\kt841\Documents\SocialMedia\social_media\post\views.py changed, reloading.
Watching for file changes with StatReloader
C:\Users\kt841\Documents\SocialMedia\social_media\post\views.py changed, reloading.
Watching for file changes with StatReloader
C:\Users\kt841\Documents\SocialMedia\social_media\post\views.py changed, reloading.
Watching for file changes with StatReloader
C:\Users\kt841\Documents\SocialMedia\social_media\post\views.py changed, reloading.
Watching for file changes with StatReloader
C:\Users\kt841\Documents\SocialMedia\social_media\post\views.py changed, reloading.
Watching for file changes with StatReloader
C:\Users\kt841\Documents\SocialMedia\social_media\post\views.py changed, reloading.
Watching for file changes with StatReloader
C:\Users\kt841\Documents\SocialMedia\social_media\post\views.py changed, reloading.
Watching for file changes with StatReloader
C:\Users\kt841\Documents\SocialMedia\social_media\post\views.py changed, reloading.
Watching for file changes with StatReloader
C:\Users\kt841\Documents\SocialMedia\social_media\post\views.py changed, reloading.
Watching for file changes with StatReloader
C:\Users\kt841\Documents\SocialMedia\social_media\post\views.py changed, reloading.
Watching for file changes with StatReloader
C:\Users\kt841\Documents\SocialMedia\social_media\post\views.py changed, reloading.
Watching for file changes with StatReloader
C:\Users\kt841\Documents\SocialMedia\social_media\post\views.py changed, reloading.
Watching for file changes with StatReloader
C:\Users\kt841\Documents\SocialMedia\social_media\post\views.py changed, reloading.
Watching for file changes with StatReloader
C:\Users\kt841\Documents\SocialMedia\social_media\post\urls.py changed, reloading.
Watching for file changes with StatReloader
C:\Users\kt841\Documents\SocialMedia\social_media\post\urls.py changed, reloading.
Watching for file changes with StatReloader
C:\Users\kt841\Documents\SocialMedia\social_media\post\urls.py changed, reloading.
Watching for file changes with StatReloader
C:\Users\kt841\Documents\SocialMedia\social_media\post\urls.py changed, reloading.
Watching for file changes with StatReloader
C:\Users\kt841\Documents\SocialMedia\social_media\post\urls.py changed, reloading.
Watching for file changes with StatReloader
C:\Users\kt841\Documents\SocialMedia\social_media\post\urls.py changed, reloading.
Watching for file changes with StatReloader
C:\Users\kt841\Documents\SocialMedia\social_media\post\urls.py changed, reloading.
Watching for file changes with StatReloader
Not Found: /blog/
"GET /blog/ HTTP/1.1" 404 4527
Not Found: /favicon.ico
"GET /favicon.ico HTTP/1.1" 404 4545
"GET /comment HTTP/1.1" 301 0
"GET /comment/ HTTP/1.1" 200 5279
C:\Users\kt841\Documents\SocialMedia\social_media\post\urls.py changed, reloading.
Watching for file changes with StatReloader
C:\Users\kt841\Documents\SocialMedia\social_media\post\urls.py changed, reloading.
Watching for file changes with StatReloader
C:\Users\kt841\Documents\SocialMedia\social_media\post\urls.py changed, reloading.
Watching for file changes with StatReloader
C:\Users\kt841\Documents\SocialMedia\social_media\post\urls.py changed, reloading.
Watching for file changes with StatReloader
C:\Users\kt841\Documents\SocialMedia\social_media\post\urls.py changed, reloading.
Watching for file changes with StatReloader
C:\Users\kt841\Documents\SocialMedia\social_media\post\urls.py changed, reloading.
Watching for file changes with StatReloader
Not Found: /post/cooment/
"POST /post/cooment/ HTTP/1.1" 404 4577
Not Found: /post/comment/
"POST /post/comment/ HTTP/1.1" 404 4577
Not Found: /post/comment/
"POST /post/comment/ HTTP/1.1" 404 4577
Watching for file changes with StatReloader
Not Found: /post/comment/
"POST /post/comment/ HTTP/1.1" 404 4577
Method Not Allowed: /post/comment
"POST /post/comment HTTP/1.1" 405 41
Not Found: /post/comment/
"POST /post/comment/ HTTP/1.1" 404 4577
Not Found: /post/comment/
"POST /post/comment/ HTTP/1.1" 404 4577
"GET / HTTP/1.1" 200 5312
Not Found: /favicon.ico
"GET /favicon.ico HTTP/1.1" 404 4570
"POST /api/token/ HTTP/1.1" 200 483
"GET /user/profile HTTP/1.1" 301 0
Internal Server Error: /user/profile/
Traceback (most recent call last):
  File "C:\Users\kt841\Documents\SocialMedia\venv\Lib\site-packages\django\core\handlers\exception.py", line 55, in inner
    response = get_response(request)
               ^^^^^^^^^^^^^^^^^^^^^
  File "C:\Users\kt841\Documents\SocialMedia\venv\Lib\site-packages\django\core\handlers\base.py", line 197, in _get_response
    response = wrapped_callback(request, *callback_args, **callback_kwargs)
               ^^^^^^^^^^^^^^^^^^^^^^^^^^^^^^^^^^^^^^^^^^^^^^^^^^^^^^^^^^^^
  File "C:\Users\kt841\Documents\SocialMedia\venv\Lib\site-packages\django\views\decorators\csrf.py", line 56, in wrapper_view
    return view_func(*args, **kwargs)
           ^^^^^^^^^^^^^^^^^^^^^^^^^^
  File "C:\Users\kt841\Documents\SocialMedia\venv\Lib\site-packages\django\views\generic\base.py", line 104, in view
    return self.dispatch(request, *args, **kwargs)
           ^^^^^^^^^^^^^^^^^^^^^^^^^^^^^^^^^^^^^^^
  File "C:\Users\kt841\Documents\SocialMedia\venv\Lib\site-packages\rest_framework\views.py", line 509, in dispatch
    response = self.handle_exception(exc)
               ^^^^^^^^^^^^^^^^^^^^^^^^^^
  File "C:\Users\kt841\Documents\SocialMedia\venv\Lib\site-packages\rest_framework\views.py", line 469, in handle_exception
    self.raise_uncaught_exception(exc)
  File "C:\Users\kt841\Documents\SocialMedia\venv\Lib\site-packages\rest_framework\views.py", line 480, in raise_uncaught_exception
    raise exc
  File "C:\Users\kt841\Documents\SocialMedia\venv\Lib\site-packages\rest_framework\views.py", line 506, in dispatch
    response = handler(request, *args, **kwargs)
               ^^^^^^^^^^^^^^^^^^^^^^^^^^^^^^^^^
  File "C:\Users\kt841\Documents\SocialMedia\social_media\user_profile\views.py", line 34, in get
    'created_at': profile.user.created_at,
                  ^^^^^^^^^^^^^^^^^^^^^^^
AttributeError: 'User' object has no attribute 'created_at'
"GET /user/profile/ HTTP/1.1" 500 92998
C:\Users\kt841\Documents\SocialMedia\social_media\user_profile\views.py changed, reloading.
Watching for file changes with StatReloader
"GET /user/profile HTTP/1.1" 301 0
Internal Server Error: /user/profile/
Traceback (most recent call last):
  File "C:\Users\kt841\Documents\SocialMedia\venv\Lib\site-packages\django\core\handlers\exception.py", line 55, in inner
    response = get_response(request)
               ^^^^^^^^^^^^^^^^^^^^^
  File "C:\Users\kt841\Documents\SocialMedia\venv\Lib\site-packages\django\core\handlers\base.py", line 197, in _get_response
    response = wrapped_callback(request, *callback_args, **callback_kwargs)
               ^^^^^^^^^^^^^^^^^^^^^^^^^^^^^^^^^^^^^^^^^^^^^^^^^^^^^^^^^^^^
  File "C:\Users\kt841\Documents\SocialMedia\venv\Lib\site-packages\django\views\decorators\csrf.py", line 56, in wrapper_view
    return view_func(*args, **kwargs)
           ^^^^^^^^^^^^^^^^^^^^^^^^^^
  File "C:\Users\kt841\Documents\SocialMedia\venv\Lib\site-packages\django\views\generic\base.py", line 104, in view
    return self.dispatch(request, *args, **kwargs)
           ^^^^^^^^^^^^^^^^^^^^^^^^^^^^^^^^^^^^^^^
  File "C:\Users\kt841\Documents\SocialMedia\venv\Lib\site-packages\rest_framework\views.py", line 509, in dispatch
    response = self.handle_exception(exc)
               ^^^^^^^^^^^^^^^^^^^^^^^^^^
  File "C:\Users\kt841\Documents\SocialMedia\venv\Lib\site-packages\rest_framework\views.py", line 469, in handle_exception
    self.raise_uncaught_exception(exc)
  File "C:\Users\kt841\Documents\SocialMedia\venv\Lib\site-packages\rest_framework\views.py", line 480, in raise_uncaught_exception
    raise exc
  File "C:\Users\kt841\Documents\SocialMedia\venv\Lib\site-packages\rest_framework\views.py", line 506, in dispatch
    response = handler(request, *args, **kwargs)
               ^^^^^^^^^^^^^^^^^^^^^^^^^^^^^^^^^
  File "C:\Users\kt841\Documents\SocialMedia\social_media\user_profile\views.py", line 35, in get
    'modified_at': profile.user.modified_at
                   ^^^^^^^^^^^^^^^^^^^^^^^^
AttributeError: 'User' object has no attribute 'modified_at'
"GET /user/profile/ HTTP/1.1" 500 92966
C:\Users\kt841\Documents\SocialMedia\social_media\user_profile\views.py changed, reloading.
Watching for file changes with StatReloader
"GET /user/profile HTTP/1.1" 301 0
"GET /user/profile/ HTTP/1.1" 200 145
"POST /api/token/ HTTP/1.1" 200 483
"GET /user/profile HTTP/1.1" 301 0
"GET /user/profile/ HTTP/1.1" 200 144
"GET /post HTTP/1.1" 301 0
"GET /post/ HTTP/1.1" 200 786
Not Found: /post/comment/
"POST /post/comment/ HTTP/1.1" 404 4577
Not Found: /post/comment/
"POST /post/comment/ HTTP/1.1" 404 4577
C:\Users\kt841\Documents\SocialMedia\social_media\post\urls.py changed, reloading.
Watching for file changes with StatReloader
Not Found: /post/comment/
"POST /post/comment/ HTTP/1.1" 404 4578
Unauthorized: /post/
"GET /post/ HTTP/1.1" 401 5180
Unauthorized: /post/
"GET /post/ HTTP/1.1" 401 5180
Unauthorized: /post/
"GET /post/ HTTP/1.1" 401 5180
"GET /api-auth/login/?next=/post/ HTTP/1.1" 200 2706
"POST /api-auth/login/ HTTP/1.1" 302 0
Unauthorized: /post/
"GET /post/ HTTP/1.1" 401 5180
"GET /api-auth/login/?next=/post/ HTTP/1.1" 200 2706
"POST /api-auth/login/ HTTP/1.1" 302 0
Unauthorized: /post/
"GET /post/ HTTP/1.1" 401 5180
Unauthorized: /post/
"GET /post/ HTTP/1.1" 401 5180
Unauthorized: /post/
"GET /post/ HTTP/1.1" 401 5180
"POST /api/token/ HTTP/1.1" 200 483
"GET /api-auth/login/?next=/post/ HTTP/1.1" 200 2706
"POST /api-auth/login/ HTTP/1.1" 302 0
Unauthorized: /post/
"GET /post/ HTTP/1.1" 401 5180
Unauthorized: /post/
"GET /post/ HTTP/1.1" 401 5180
Unauthorized: /post/
"GET /post/ HTTP/1.1" 401 5180
Unauthorized: /post/
"GET /post/ HTTP/1.1" 401 5180
Unauthorized: /post/
"GET /post/ HTTP/1.1" 401 5180
"GET /api-auth/login/?next=/post/ HTTP/1.1" 200 2706
Unauthorized: /post/
"GET /post/ HTTP/1.1" 401 5180
"GET /api-auth/login/?next=/post/ HTTP/1.1" 200 2706
Unauthorized: /post/
"GET /post/ HTTP/1.1" 401 5180
"GET /api-auth/login/?next=/post/ HTTP/1.1" 200 2706
Unauthorized: /post/
"GET /post/ HTTP/1.1" 401 5180
"GET / HTTP/1.1" 200 5312
"GET /post HTTP/1.1" 301 0
"GET /post/ HTTP/1.1" 200 786
Internal Server Error: /post/delete
Traceback (most recent call last):
  File "C:\Users\kt841\Documents\SocialMedia\venv\Lib\site-packages\django\core\handlers\exception.py", line 55, in inner
    response = get_response(request)
               ^^^^^^^^^^^^^^^^^^^^^
  File "C:\Users\kt841\Documents\SocialMedia\venv\Lib\site-packages\django\utils\deprecation.py", line 136, in __call__
    response = self.process_response(request, response)
               ^^^^^^^^^^^^^^^^^^^^^^^^^^^^^^^^^^^^^^^^
  File "C:\Users\kt841\Documents\SocialMedia\venv\Lib\site-packages\django\middleware\common.py", line 108, in process_response
    return self.response_redirect_class(self.get_full_path_with_slash(request))
                                        ^^^^^^^^^^^^^^^^^^^^^^^^^^^^^^^^^^^^^^
  File "C:\Users\kt841\Documents\SocialMedia\venv\Lib\site-packages\django\middleware\common.py", line 87, in get_full_path_with_slash
    raise RuntimeError(
RuntimeError: You called this URL via POST, but the URL doesn't end in a slash and you have APPEND_SLASH set. Django can't redirect to the slash URL while maintaining POST data. Change your form to point to 127.0.0.1:8000/post/delete/ (note the trailing slash), or set APPEND_SLASH=False in your Django settings.
"POST /post/delete HTTP/1.1" 500 70024
"POST /post/delete/ HTTP/1.1" 204 63
Not Found: /post/comment/
"POST /post/comment/ HTTP/1.1" 404 4578
Not Found: /post/comment/
"GET /post/comment/ HTTP/1.1" 404 4577
Not Found: /post/comment/
"GET /post/comment/ HTTP/1.1" 404 4577
Not Found: /post/comment/
"POST /post/comment/ HTTP/1.1" 404 4578
Not Found: /post/comment/
"POST /post/comment/ HTTP/1.1" 404 4578
C:\Users\kt841\Documents\SocialMedia\social_media\post\urls.py changed, reloading.
Watching for file changes with StatReloader
C:\Users\kt841\Documents\SocialMedia\social_media\post\urls.py changed, reloading.
Watching for file changes with StatReloader
C:\Users\kt841\Documents\SocialMedia\social_media\post\urls.py changed, reloading.
Watching for file changes with StatReloader
Method Not Allowed: /post/comment/
"POST /post/comment/ HTTP/1.1" 405 41
C:\Users\kt841\Documents\SocialMedia\social_media\post\urls.py changed, reloading.
Watching for file changes with StatReloader
Method Not Allowed: /post/comment/
"POST /post/comment/ HTTP/1.1" 405 41
Method Not Allowed: /post/comment/
"POST /post/comment/ HTTP/1.1" 405 41
Not Found: /post/comment/1
"POST /post/comment/1 HTTP/1.1" 404 4582
Internal Server Error: /post/comment
Traceback (most recent call last):
  File "C:\Users\kt841\Documents\SocialMedia\venv\Lib\site-packages\django\core\handlers\exception.py", line 55, in inner
    response = get_response(request)
               ^^^^^^^^^^^^^^^^^^^^^
  File "C:\Users\kt841\Documents\SocialMedia\venv\Lib\site-packages\django\utils\deprecation.py", line 136, in __call__
    response = self.process_response(request, response)
               ^^^^^^^^^^^^^^^^^^^^^^^^^^^^^^^^^^^^^^^^
  File "C:\Users\kt841\Documents\SocialMedia\venv\Lib\site-packages\django\middleware\common.py", line 108, in process_response
    return self.response_redirect_class(self.get_full_path_with_slash(request))
                                        ^^^^^^^^^^^^^^^^^^^^^^^^^^^^^^^^^^^^^^
  File "C:\Users\kt841\Documents\SocialMedia\venv\Lib\site-packages\django\middleware\common.py", line 87, in get_full_path_with_slash
    raise RuntimeError(
RuntimeError: You called this URL via POST, but the URL doesn't end in a slash and you have APPEND_SLASH set. Django can't redirect to the slash URL while maintaining POST data. Change your form to point to 127.0.0.1:8000/post/comment/ (note the trailing slash), or set APPEND_SLASH=False in your Django settings.
"POST /post/comment HTTP/1.1" 500 70041
"GET /post/comment HTTP/1.1" 301 0
"GET /post/comment/ HTTP/1.1" 200 2
C:\Users\kt841\Documents\SocialMedia\social_media\post\views.py changed, reloading.
Watching for file changes with StatReloader
C:\Users\kt841\Documents\SocialMedia\social_media\post\views.py changed, reloading.
Watching for file changes with StatReloader
C:\Users\kt841\Documents\SocialMedia\social_media\post\views.py changed, reloading.
Watching for file changes with StatReloader
C:\Users\kt841\Documents\SocialMedia\social_media\post\views.py changed, reloading.
Watching for file changes with StatReloader
C:\Users\kt841\Documents\SocialMedia\social_media\post\views.py changed, reloading.
Watching for file changes with StatReloader
C:\Users\kt841\Documents\SocialMedia\social_media\post\views.py changed, reloading.
Watching for file changes with StatReloader
"GET /post/comment HTTP/1.1" 301 0
"GET /post/comment/ HTTP/1.1" 200 2
C:\Users\kt841\Documents\SocialMedia\social_media\post\views.py changed, reloading.
Watching for file changes with StatReloader
C:\Users\kt841\Documents\SocialMedia\social_media\post\views.py changed, reloading.
Watching for file changes with StatReloader
C:\Users\kt841\Documents\SocialMedia\social_media\post\views.py changed, reloading.
Watching for file changes with StatReloader
"GET /post/comment/ HTTP/1.1" 200 2
C:\Users\kt841\Documents\SocialMedia\social_media\post\views.py changed, reloading.
Watching for file changes with StatReloader
C:\Users\kt841\Documents\SocialMedia\social_media\post\views.py changed, reloading.
Watching for file changes with StatReloader
C:\Users\kt841\Documents\SocialMedia\social_media\post\views.py changed, reloading.
Watching for file changes with StatReloader
C:\Users\kt841\Documents\SocialMedia\social_media\post\views.py changed, reloading.
Watching for file changes with StatReloader
C:\Users\kt841\Documents\SocialMedia\social_media\post\views.py changed, reloading.
Watching for file changes with StatReloader
C:\Users\kt841\Documents\SocialMedia\social_media\post\views.py changed, reloading.
Watching for file changes with StatReloader
"GET /post/comment/ HTTP/1.1" 200 2
C:\Users\kt841\Documents\SocialMedia\social_media\post\views.py changed, reloading.
Watching for file changes with StatReloader
C:\Users\kt841\Documents\SocialMedia\social_media\post\views.py changed, reloading.
Watching for file changes with StatReloader
C:\Users\kt841\Documents\SocialMedia\social_media\post\views.py changed, reloading.
Watching for file changes with StatReloader
C:\Users\kt841\Documents\SocialMedia\social_media\post\views.py changed, reloading.
Watching for file changes with StatReloader
C:\Users\kt841\Documents\SocialMedia\social_media\post\views.py changed, reloading.
Watching for file changes with StatReloader
C:\Users\kt841\Documents\SocialMedia\social_media\post\views.py changed, reloading.
Watching for file changes with StatReloader
C:\Users\kt841\Documents\SocialMedia\social_media\post\views.py changed, reloading.
Watching for file changes with StatReloader
"GET /post/like/ HTTP/1.1" 200 151
Not Found: /post/like/1
"GET /post/like/1 HTTP/1.1" 404 4572
"GET /post/like/ HTTP/1.1" 200 151
C:\Users\kt841\Documents\SocialMedia\social_media\post\views.py changed, reloading.
Watching for file changes with StatReloader
"GET /post/like/ HTTP/1.1" 200 151
C:\Users\kt841\Documents\SocialMedia\social_media\post\views.py changed, reloading.
Watching for file changes with StatReloader
Not Found: /post/like/47768907-bae8-4784-b40d-e8de3784f5f0
"GET /post/like/47768907-bae8-4784-b40d-e8de3784f5f0 HTTP/1.1" 404 4677
"GET /post/like/ HTTP/1.1" 200 151
Internal Server Error: /post/like/
Traceback (most recent call last):
  File "C:\Users\kt841\Documents\SocialMedia\venv\Lib\site-packages\django\db\backends\utils.py", line 89, in _execute
    return self.cursor.execute(sql, params)
           ^^^^^^^^^^^^^^^^^^^^^^^^^^^^^^^^
  File "C:\Users\kt841\Documents\SocialMedia\venv\Lib\site-packages\django\db\backends\mysql\base.py", line 75, in execute
    return self.cursor.execute(query, args)
           ^^^^^^^^^^^^^^^^^^^^^^^^^^^^^^^^
  File "C:\Users\kt841\Documents\SocialMedia\venv\Lib\site-packages\MySQLdb\cursors.py", line 179, in execute
    res = self._query(mogrified_query)
          ^^^^^^^^^^^^^^^^^^^^^^^^^^^^
  File "C:\Users\kt841\Documents\SocialMedia\venv\Lib\site-packages\MySQLdb\cursors.py", line 330, in _query
    db.query(q)
  File "C:\Users\kt841\Documents\SocialMedia\venv\Lib\site-packages\MySQLdb\connections.py", line 255, in query
    _mysql.connection.query(self, query)
MySQLdb.IntegrityError: (1048, "Column 'user_id' cannot be null")

The above exception was the direct cause of the following exception:

Traceback (most recent call last):
  File "C:\Users\kt841\Documents\SocialMedia\venv\Lib\site-packages\django\core\handlers\exception.py", line 55, in inner
    response = get_response(request)
               ^^^^^^^^^^^^^^^^^^^^^
  File "C:\Users\kt841\Documents\SocialMedia\venv\Lib\site-packages\django\core\handlers\base.py", line 197, in _get_response
    response = wrapped_callback(request, *callback_args, **callback_kwargs)
               ^^^^^^^^^^^^^^^^^^^^^^^^^^^^^^^^^^^^^^^^^^^^^^^^^^^^^^^^^^^^
  File "C:\Users\kt841\Documents\SocialMedia\venv\Lib\site-packages\django\views\decorators\csrf.py", line 56, in wrapper_view
    return view_func(*args, **kwargs)
           ^^^^^^^^^^^^^^^^^^^^^^^^^^
  File "C:\Users\kt841\Documents\SocialMedia\venv\Lib\site-packages\django\views\generic\base.py", line 104, in view
    return self.dispatch(request, *args, **kwargs)
           ^^^^^^^^^^^^^^^^^^^^^^^^^^^^^^^^^^^^^^^
  File "C:\Users\kt841\Documents\SocialMedia\venv\Lib\site-packages\rest_framework\views.py", line 509, in dispatch
    response = self.handle_exception(exc)
               ^^^^^^^^^^^^^^^^^^^^^^^^^^
  File "C:\Users\kt841\Documents\SocialMedia\venv\Lib\site-packages\rest_framework\views.py", line 469, in handle_exception
    self.raise_uncaught_exception(exc)
  File "C:\Users\kt841\Documents\SocialMedia\venv\Lib\site-packages\rest_framework\views.py", line 480, in raise_uncaught_exception
    raise exc
  File "C:\Users\kt841\Documents\SocialMedia\venv\Lib\site-packages\rest_framework\views.py", line 506, in dispatch
    response = handler(request, *args, **kwargs)
               ^^^^^^^^^^^^^^^^^^^^^^^^^^^^^^^^^
  File "C:\Users\kt841\Documents\SocialMedia\social_media\post\views.py", line 111, in post
    like_object.save()
  File "C:\Users\kt841\Documents\SocialMedia\social_media\post\models.py", line 29, in save
    super().save(*args, **kwargs)
  File "C:\Users\kt841\Documents\SocialMedia\venv\Lib\site-packages\django\db\models\base.py", line 814, in save
    self.save_base(
  File "C:\Users\kt841\Documents\SocialMedia\venv\Lib\site-packages\django\db\models\base.py", line 877, in save_base
    updated = self._save_table(
              ^^^^^^^^^^^^^^^^^
  File "C:\Users\kt841\Documents\SocialMedia\venv\Lib\site-packages\django\db\models\base.py", line 1020, in _save_table
    results = self._do_insert(
              ^^^^^^^^^^^^^^^^
  File "C:\Users\kt841\Documents\SocialMedia\venv\Lib\site-packages\django\db\models\base.py", line 1061, in _do_insert
    return manager._insert(
           ^^^^^^^^^^^^^^^^
  File "C:\Users\kt841\Documents\SocialMedia\venv\Lib\site-packages\django\db\models\manager.py", line 87, in manager_method
    return getattr(self.get_queryset(), name)(*args, **kwargs)
           ^^^^^^^^^^^^^^^^^^^^^^^^^^^^^^^^^^^^^^^^^^^^^^^^^^^
  File "C:\Users\kt841\Documents\SocialMedia\venv\Lib\site-packages\django\db\models\query.py", line 1805, in _insert
    return query.get_compiler(using=using).execute_sql(returning_fields)
           ^^^^^^^^^^^^^^^^^^^^^^^^^^^^^^^^^^^^^^^^^^^^^^^^^^^^^^^^^^^^^
  File "C:\Users\kt841\Documents\SocialMedia\venv\Lib\site-packages\django\db\models\sql\compiler.py", line 1822, in execute_sql
    cursor.execute(sql, params)
  File "C:\Users\kt841\Documents\SocialMedia\venv\Lib\site-packages\django\db\backends\utils.py", line 102, in execute
    return super().execute(sql, params)
           ^^^^^^^^^^^^^^^^^^^^^^^^^^^^
  File "C:\Users\kt841\Documents\SocialMedia\venv\Lib\site-packages\django\db\backends\utils.py", line 67, in execute
    return self._execute_with_wrappers(
           ^^^^^^^^^^^^^^^^^^^^^^^^^^^^
  File "C:\Users\kt841\Documents\SocialMedia\venv\Lib\site-packages\django\db\backends\utils.py", line 80, in _execute_with_wrappers
    return executor(sql, params, many, context)
           ^^^^^^^^^^^^^^^^^^^^^^^^^^^^^^^^^^^^
  File "C:\Users\kt841\Documents\SocialMedia\venv\Lib\site-packages\django\db\backends\utils.py", line 84, in _execute
    with self.db.wrap_database_errors:
  File "C:\Users\kt841\Documents\SocialMedia\venv\Lib\site-packages\django\db\utils.py", line 91, in __exit__
    raise dj_exc_value.with_traceback(traceback) from exc_value
  File "C:\Users\kt841\Documents\SocialMedia\venv\Lib\site-packages\django\db\backends\utils.py", line 89, in _execute
    return self.cursor.execute(sql, params)
           ^^^^^^^^^^^^^^^^^^^^^^^^^^^^^^^^
  File "C:\Users\kt841\Documents\SocialMedia\venv\Lib\site-packages\django\db\backends\mysql\base.py", line 75, in execute
    return self.cursor.execute(query, args)
           ^^^^^^^^^^^^^^^^^^^^^^^^^^^^^^^^
  File "C:\Users\kt841\Documents\SocialMedia\venv\Lib\site-packages\MySQLdb\cursors.py", line 179, in execute
    res = self._query(mogrified_query)
          ^^^^^^^^^^^^^^^^^^^^^^^^^^^^
  File "C:\Users\kt841\Documents\SocialMedia\venv\Lib\site-packages\MySQLdb\cursors.py", line 330, in _query
    db.query(q)
  File "C:\Users\kt841\Documents\SocialMedia\venv\Lib\site-packages\MySQLdb\connections.py", line 255, in query
    _mysql.connection.query(self, query)
django.db.utils.IntegrityError: (1048, "Column 'user_id' cannot be null")
"POST /post/like/ HTTP/1.1" 500 200626
Unsupported Media Type: /post/like/
"POST /post/like/ HTTP/1.1" 415 62
Unsupported Media Type: /post/like/
"POST /post/like/ HTTP/1.1" 415 62
Unsupported Media Type: /post/like/
"POST /post/like/ HTTP/1.1" 415 62
Unsupported Media Type: /post/like/
"POST /post/like/ HTTP/1.1" 415 62
"GET /users/ HTTP/1.1" 200 949
Unsupported Media Type: /post/like/
"POST /post/like/ HTTP/1.1" 415 62
Unsupported Media Type: /post/like/
"POST /post/like/ HTTP/1.1" 415 62
C:\Users\kt841\Documents\SocialMedia\social_media\post\views.py changed, reloading.
Watching for file changes with StatReloader
C:\Users\kt841\Documents\SocialMedia\social_media\post\views.py changed, reloading.
Watching for file changes with StatReloader
C:\Users\kt841\Documents\SocialMedia\social_media\post\views.py changed, reloading.
Watching for file changes with StatReloader
C:\Users\kt841\Documents\SocialMedia\social_media\post\views.py changed, reloading.
Watching for file changes with StatReloader
Unsupported Media Type: /post/like/
"POST /post/like/ HTTP/1.1" 415 62
C:\Users\kt841\Documents\SocialMedia\social_media\post\views.py changed, reloading.
Watching for file changes with StatReloader
Not Found: /post/like/1
"POST /post/like/1 HTTP/1.1" 404 4573
Not Found: /post/like/0a56a3dd-ae07-43ce-b29c-48fbb7fa3fae
"POST /post/like/0a56a3dd-ae07-43ce-b29c-48fbb7fa3fae HTTP/1.1" 404 4678
Not Found: /post/like/'0a56a3dd-ae07-43ce-b29c-48fbb7fa3fae'
"POST /post/like/'0a56a3dd-ae07-43ce-b29c-48fbb7fa3fae' HTTP/1.1" 404 4714
"GET /post/like/ HTTP/1.1" 200 151
Unsupported Media Type: /post/like/
"POST /post/like/ HTTP/1.1" 415 62
Unsupported Media Type: /post/like/
"POST /post/like/ HTTP/1.1" 415 62
"POST /api/token/ HTTP/1.1" 200 483
Unsupported Media Type: /post/like/
"POST /post/like/ HTTP/1.1" 415 62
C:\Users\kt841\Documents\SocialMedia\social_media\post\views.py changed, reloading.
Watching for file changes with StatReloader
C:\Users\kt841\Documents\SocialMedia\social_media\post\views.py changed, reloading.
Watching for file changes with StatReloader
C:\Users\kt841\Documents\SocialMedia\social_media\post\views.py changed, reloading.
Watching for file changes with StatReloader
"GET /post/like/ HTTP/1.1" 200 151
C:\Users\kt841\Documents\SocialMedia\social_media\post\views.py changed, reloading.
Watching for file changes with StatReloader
C:\Users\kt841\Documents\SocialMedia\social_media\post\views.py changed, reloading.
Watching for file changes with StatReloader
C:\Users\kt841\Documents\SocialMedia\social_media\post\views.py changed, reloading.
Watching for file changes with StatReloader
"POST /api/token/ HTTP/1.1" 200 483
"GET /post HTTP/1.1" 301 0
"GET /post/ HTTP/1.1" 200 629
C:\Users\kt841\Documents\SocialMedia\social_media\post\views.py changed, reloading.
Watching for file changes with StatReloader
C:\Users\kt841\Documents\SocialMedia\social_media\post\views.py changed, reloading.
Watching for file changes with StatReloader
C:\Users\kt841\Documents\SocialMedia\social_media\post\views.py changed, reloading.
Watching for file changes with StatReloader
C:\Users\kt841\Documents\SocialMedia\social_media\post\views.py changed, reloading.
Watching for file changes with StatReloader
C:\Users\kt841\Documents\SocialMedia\social_media\post\views.py changed, reloading.
Watching for file changes with StatReloader
C:\Users\kt841\Documents\SocialMedia\social_media\post\views.py changed, reloading.
Watching for file changes with StatReloader
C:\Users\kt841\Documents\SocialMedia\social_media\post\views.py changed, reloading.
Watching for file changes with StatReloader
C:\Users\kt841\Documents\SocialMedia\social_media\post\views.py changed, reloading.
Watching for file changes with StatReloader
C:\Users\kt841\Documents\SocialMedia\social_media\post\views.py changed, reloading.
Watching for file changes with StatReloader
C:\Users\kt841\Documents\SocialMedia\social_media\post\views.py changed, reloading.
Watching for file changes with StatReloader
C:\Users\kt841\Documents\SocialMedia\social_media\post\views.py changed, reloading.
Watching for file changes with StatReloader
C:\Users\kt841\Documents\SocialMedia\social_media\post\views.py changed, reloading.
Watching for file changes with StatReloader
C:\Users\kt841\Documents\SocialMedia\social_media\post\views.py changed, reloading.
Watching for file changes with StatReloader
C:\Users\kt841\Documents\SocialMedia\social_media\post\views.py changed, reloading.
Watching for file changes with StatReloader
C:\Users\kt841\Documents\SocialMedia\social_media\post\views.py changed, reloading.
Watching for file changes with StatReloader
C:\Users\kt841\Documents\SocialMedia\social_media\post\views.py changed, reloading.
Watching for file changes with StatReloader
C:\Users\kt841\Documents\SocialMedia\social_media\post\views.py changed, reloading.
Watching for file changes with StatReloader
C:\Users\kt841\Documents\SocialMedia\social_media\post\views.py changed, reloading.
Watching for file changes with StatReloader
C:\Users\kt841\Documents\SocialMedia\social_media\post\views.py changed, reloading.
Watching for file changes with StatReloader
C:\Users\kt841\Documents\SocialMedia\social_media\post\views.py changed, reloading.
Watching for file changes with StatReloader
C:\Users\kt841\Documents\SocialMedia\social_media\post\views.py changed, reloading.
Watching for file changes with StatReloader
C:\Users\kt841\Documents\SocialMedia\social_media\post\views.py changed, reloading.
Watching for file changes with StatReloader
Unauthorized: /post/1
"GET /post/1 HTTP/1.1" 401 183
"POST /api/token/refresh/ HTTP/1.1" 200 241
Internal Server Error: /post/1
Traceback (most recent call last):
  File "C:\Users\kt841\Documents\SocialMedia\venv\Lib\site-packages\django\core\handlers\exception.py", line 55, in inner
    response = get_response(request)
               ^^^^^^^^^^^^^^^^^^^^^
  File "C:\Users\kt841\Documents\SocialMedia\venv\Lib\site-packages\django\core\handlers\base.py", line 197, in _get_response
    response = wrapped_callback(request, *callback_args, **callback_kwargs)
               ^^^^^^^^^^^^^^^^^^^^^^^^^^^^^^^^^^^^^^^^^^^^^^^^^^^^^^^^^^^^
  File "C:\Users\kt841\Documents\SocialMedia\venv\Lib\site-packages\django\views\decorators\csrf.py", line 56, in wrapper_view
    return view_func(*args, **kwargs)
           ^^^^^^^^^^^^^^^^^^^^^^^^^^
  File "C:\Users\kt841\Documents\SocialMedia\venv\Lib\site-packages\django\views\generic\base.py", line 104, in view
    return self.dispatch(request, *args, **kwargs)
           ^^^^^^^^^^^^^^^^^^^^^^^^^^^^^^^^^^^^^^^
  File "C:\Users\kt841\Documents\SocialMedia\venv\Lib\site-packages\rest_framework\views.py", line 509, in dispatch
    response = self.handle_exception(exc)
               ^^^^^^^^^^^^^^^^^^^^^^^^^^
  File "C:\Users\kt841\Documents\SocialMedia\venv\Lib\site-packages\rest_framework\views.py", line 469, in handle_exception
    self.raise_uncaught_exception(exc)
  File "C:\Users\kt841\Documents\SocialMedia\venv\Lib\site-packages\rest_framework\views.py", line 480, in raise_uncaught_exception
    raise exc
  File "C:\Users\kt841\Documents\SocialMedia\venv\Lib\site-packages\rest_framework\views.py", line 506, in dispatch
    response = handler(request, *args, **kwargs)
               ^^^^^^^^^^^^^^^^^^^^^^^^^^^^^^^^^
  File "C:\Users\kt841\Documents\SocialMedia\social_media\post\views.py", line 24, in get
    for post in Post.objects.get(user_id=id):
                ^^^^^^^^^^^^^^^^^^^^^^^^^^^^
  File "C:\Users\kt841\Documents\SocialMedia\venv\Lib\site-packages\django\db\models\manager.py", line 87, in manager_method
    return getattr(self.get_queryset(), name)(*args, **kwargs)
           ^^^^^^^^^^^^^^^^^^^^^^^^^^^^^^^^^^^^^^^^^^^^^^^^^^^
  File "C:\Users\kt841\Documents\SocialMedia\venv\Lib\site-packages\django\db\models\query.py", line 640, in get
    raise self.model.MultipleObjectsReturned(
post.models.Post.MultipleObjectsReturned: get() returned more than one Post -- it returned 4!
"GET /post/1 HTTP/1.1" 500 101755
C:\Users\kt841\Documents\SocialMedia\social_media\post\views.py changed, reloading.
Watching for file changes with StatReloader
C:\Users\kt841\Documents\SocialMedia\social_media\post\views.py changed, reloading.
Watching for file changes with StatReloader
C:\Users\kt841\Documents\SocialMedia\social_media\post\views.py changed, reloading.
Watching for file changes with StatReloader
C:\Users\kt841\Documents\SocialMedia\social_media\post\views.py changed, reloading.
Watching for file changes with StatReloader
Internal Server Error: /post/1
Traceback (most recent call last):
  File "C:\Users\kt841\Documents\SocialMedia\venv\Lib\site-packages\django\core\handlers\exception.py", line 55, in inner
    response = get_response(request)
               ^^^^^^^^^^^^^^^^^^^^^
  File "C:\Users\kt841\Documents\SocialMedia\venv\Lib\site-packages\django\core\handlers\base.py", line 197, in _get_response
    response = wrapped_callback(request, *callback_args, **callback_kwargs)
               ^^^^^^^^^^^^^^^^^^^^^^^^^^^^^^^^^^^^^^^^^^^^^^^^^^^^^^^^^^^^
  File "C:\Users\kt841\Documents\SocialMedia\venv\Lib\site-packages\django\views\decorators\csrf.py", line 56, in wrapper_view
    return view_func(*args, **kwargs)
           ^^^^^^^^^^^^^^^^^^^^^^^^^^
  File "C:\Users\kt841\Documents\SocialMedia\venv\Lib\site-packages\django\views\generic\base.py", line 104, in view
    return self.dispatch(request, *args, **kwargs)
           ^^^^^^^^^^^^^^^^^^^^^^^^^^^^^^^^^^^^^^^
  File "C:\Users\kt841\Documents\SocialMedia\venv\Lib\site-packages\rest_framework\views.py", line 509, in dispatch
    response = self.handle_exception(exc)
               ^^^^^^^^^^^^^^^^^^^^^^^^^^
  File "C:\Users\kt841\Documents\SocialMedia\venv\Lib\site-packages\rest_framework\views.py", line 469, in handle_exception
    self.raise_uncaught_exception(exc)
  File "C:\Users\kt841\Documents\SocialMedia\venv\Lib\site-packages\rest_framework\views.py", line 480, in raise_uncaught_exception
    raise exc
  File "C:\Users\kt841\Documents\SocialMedia\venv\Lib\site-packages\rest_framework\views.py", line 506, in dispatch
    response = handler(request, *args, **kwargs)
               ^^^^^^^^^^^^^^^^^^^^^^^^^^^^^^^^^
  File "C:\Users\kt841\Documents\SocialMedia\social_media\post\views.py", line 24, in get
    for post in Post.objects.get(user_id=id):
                ^^^^^^^^^^^^^^^^^^^^^^^^^^^^
  File "C:\Users\kt841\Documents\SocialMedia\venv\Lib\site-packages\django\db\models\manager.py", line 87, in manager_method
    return getattr(self.get_queryset(), name)(*args, **kwargs)
           ^^^^^^^^^^^^^^^^^^^^^^^^^^^^^^^^^^^^^^^^^^^^^^^^^^^
  File "C:\Users\kt841\Documents\SocialMedia\venv\Lib\site-packages\django\db\models\query.py", line 640, in get
    raise self.model.MultipleObjectsReturned(
post.models.Post.MultipleObjectsReturned: get() returned more than one Post -- it returned 4!
"GET /post/1 HTTP/1.1" 500 101585
Internal Server Error: /post/2
Traceback (most recent call last):
  File "C:\Users\kt841\Documents\SocialMedia\venv\Lib\site-packages\django\core\handlers\exception.py", line 55, in inner
    response = get_response(request)
               ^^^^^^^^^^^^^^^^^^^^^
  File "C:\Users\kt841\Documents\SocialMedia\venv\Lib\site-packages\django\core\handlers\base.py", line 197, in _get_response
    response = wrapped_callback(request, *callback_args, **callback_kwargs)
               ^^^^^^^^^^^^^^^^^^^^^^^^^^^^^^^^^^^^^^^^^^^^^^^^^^^^^^^^^^^^
  File "C:\Users\kt841\Documents\SocialMedia\venv\Lib\site-packages\django\views\decorators\csrf.py", line 56, in wrapper_view
    return view_func(*args, **kwargs)
           ^^^^^^^^^^^^^^^^^^^^^^^^^^
  File "C:\Users\kt841\Documents\SocialMedia\venv\Lib\site-packages\django\views\generic\base.py", line 104, in view
    return self.dispatch(request, *args, **kwargs)
           ^^^^^^^^^^^^^^^^^^^^^^^^^^^^^^^^^^^^^^^
  File "C:\Users\kt841\Documents\SocialMedia\venv\Lib\site-packages\rest_framework\views.py", line 509, in dispatch
    response = self.handle_exception(exc)
               ^^^^^^^^^^^^^^^^^^^^^^^^^^
  File "C:\Users\kt841\Documents\SocialMedia\venv\Lib\site-packages\rest_framework\views.py", line 469, in handle_exception
    self.raise_uncaught_exception(exc)
  File "C:\Users\kt841\Documents\SocialMedia\venv\Lib\site-packages\rest_framework\views.py", line 480, in raise_uncaught_exception
    raise exc
  File "C:\Users\kt841\Documents\SocialMedia\venv\Lib\site-packages\rest_framework\views.py", line 506, in dispatch
    response = handler(request, *args, **kwargs)
               ^^^^^^^^^^^^^^^^^^^^^^^^^^^^^^^^^
  File "C:\Users\kt841\Documents\SocialMedia\social_media\post\views.py", line 24, in get
    for post in Post.objects.get(user_id=id):
                ^^^^^^^^^^^^^^^^^^^^^^^^^^^^
  File "C:\Users\kt841\Documents\SocialMedia\venv\Lib\site-packages\django\db\models\manager.py", line 87, in manager_method
    return getattr(self.get_queryset(), name)(*args, **kwargs)
           ^^^^^^^^^^^^^^^^^^^^^^^^^^^^^^^^^^^^^^^^^^^^^^^^^^^
  File "C:\Users\kt841\Documents\SocialMedia\venv\Lib\site-packages\django\db\models\query.py", line 637, in get
    raise self.model.DoesNotExist(
post.models.Post.DoesNotExist: Post matching query does not exist.
"GET /post/2 HTTP/1.1" 500 101106
C:\Users\kt841\Documents\SocialMedia\social_media\post\views.py changed, reloading.
Watching for file changes with StatReloader
C:\Users\kt841\Documents\SocialMedia\social_media\post\views.py changed, reloading.
Watching for file changes with StatReloader
C:\Users\kt841\Documents\SocialMedia\social_media\post\views.py changed, reloading.
Watching for file changes with StatReloader
C:\Users\kt841\Documents\SocialMedia\social_media\post\views.py changed, reloading.
Watching for file changes with StatReloader
C:\Users\kt841\Documents\SocialMedia\social_media\post\views.py changed, reloading.
Watching for file changes with StatReloader
C:\Users\kt841\Documents\SocialMedia\social_media\post\views.py changed, reloading.
Watching for file changes with StatReloader
C:\Users\kt841\Documents\SocialMedia\social_media\post\views.py changed, reloading.
Watching for file changes with StatReloader
C:\Users\kt841\Documents\SocialMedia\social_media\post\views.py changed, reloading.
Watching for file changes with StatReloader
C:\Users\kt841\Documents\SocialMedia\social_media\post\views.py changed, reloading.
Watching for file changes with StatReloader
C:\Users\kt841\Documents\SocialMedia\social_media\post\views.py changed, reloading.
Watching for file changes with StatReloader
C:\Users\kt841\Documents\SocialMedia\social_media\post\views.py changed, reloading.
Watching for file changes with StatReloader
C:\Users\kt841\Documents\SocialMedia\social_media\post\urls.py changed, reloading.
Watching for file changes with StatReloader
Watching for file changes with StatReloader
Internal Server Error: /post/
Traceback (most recent call last):
  File "C:\Users\kt841\Documents\SocialMedia\venv\Lib\site-packages\django\core\handlers\exception.py", line 55, in inner
    response = get_response(request)
               ^^^^^^^^^^^^^^^^^^^^^
  File "C:\Users\kt841\Documents\SocialMedia\venv\Lib\site-packages\django\core\handlers\base.py", line 197, in _get_response
    response = wrapped_callback(request, *callback_args, **callback_kwargs)
               ^^^^^^^^^^^^^^^^^^^^^^^^^^^^^^^^^^^^^^^^^^^^^^^^^^^^^^^^^^^^
  File "C:\Users\kt841\Documents\SocialMedia\venv\Lib\site-packages\django\views\decorators\csrf.py", line 56, in wrapper_view
    return view_func(*args, **kwargs)
           ^^^^^^^^^^^^^^^^^^^^^^^^^^
  File "C:\Users\kt841\Documents\SocialMedia\venv\Lib\site-packages\django\views\generic\base.py", line 104, in view
    return self.dispatch(request, *args, **kwargs)
           ^^^^^^^^^^^^^^^^^^^^^^^^^^^^^^^^^^^^^^^
  File "C:\Users\kt841\Documents\SocialMedia\venv\Lib\site-packages\rest_framework\views.py", line 509, in dispatch
    response = self.handle_exception(exc)
               ^^^^^^^^^^^^^^^^^^^^^^^^^^
  File "C:\Users\kt841\Documents\SocialMedia\venv\Lib\site-packages\rest_framework\views.py", line 469, in handle_exception
    self.raise_uncaught_exception(exc)
  File "C:\Users\kt841\Documents\SocialMedia\venv\Lib\site-packages\rest_framework\views.py", line 480, in raise_uncaught_exception
    raise exc
  File "C:\Users\kt841\Documents\SocialMedia\venv\Lib\site-packages\rest_framework\views.py", line 506, in dispatch
    response = handler(request, *args, **kwargs)
               ^^^^^^^^^^^^^^^^^^^^^^^^^^^^^^^^^
  File "C:\Users\kt841\Documents\SocialMedia\social_media\post\views.py", line 24, in get
    x = Post.objects.get(user_id=1)
        ^^^^^^^^^^^^^^^^^^^^^^^^^^^
  File "C:\Users\kt841\Documents\SocialMedia\venv\Lib\site-packages\django\db\models\manager.py", line 87, in manager_method
    return getattr(self.get_queryset(), name)(*args, **kwargs)
           ^^^^^^^^^^^^^^^^^^^^^^^^^^^^^^^^^^^^^^^^^^^^^^^^^^^
  File "C:\Users\kt841\Documents\SocialMedia\venv\Lib\site-packages\django\db\models\query.py", line 640, in get
    raise self.model.MultipleObjectsReturned(
post.models.Post.MultipleObjectsReturned: get() returned more than one Post -- it returned 4!
"GET /post/ HTTP/1.1" 500 101459
C:\Users\kt841\Documents\SocialMedia\social_media\post\views.py changed, reloading.
Watching for file changes with StatReloader
Unauthorized: /post/
"GET /post/ HTTP/1.1" 401 183
"POST /api/token/refresh/ HTTP/1.1" 200 241
Internal Server Error: /post/
Traceback (most recent call last):
  File "C:\Users\kt841\Documents\SocialMedia\venv\Lib\site-packages\django\core\handlers\exception.py", line 55, in inner
    response = get_response(request)
               ^^^^^^^^^^^^^^^^^^^^^
  File "C:\Users\kt841\Documents\SocialMedia\venv\Lib\site-packages\django\core\handlers\base.py", line 197, in _get_response
    response = wrapped_callback(request, *callback_args, **callback_kwargs)
               ^^^^^^^^^^^^^^^^^^^^^^^^^^^^^^^^^^^^^^^^^^^^^^^^^^^^^^^^^^^^
  File "C:\Users\kt841\Documents\SocialMedia\venv\Lib\site-packages\django\views\decorators\csrf.py", line 56, in wrapper_view
    return view_func(*args, **kwargs)
           ^^^^^^^^^^^^^^^^^^^^^^^^^^
  File "C:\Users\kt841\Documents\SocialMedia\venv\Lib\site-packages\django\views\generic\base.py", line 104, in view
    return self.dispatch(request, *args, **kwargs)
           ^^^^^^^^^^^^^^^^^^^^^^^^^^^^^^^^^^^^^^^
  File "C:\Users\kt841\Documents\SocialMedia\venv\Lib\site-packages\rest_framework\views.py", line 509, in dispatch
    response = self.handle_exception(exc)
               ^^^^^^^^^^^^^^^^^^^^^^^^^^
  File "C:\Users\kt841\Documents\SocialMedia\venv\Lib\site-packages\rest_framework\views.py", line 469, in handle_exception
    self.raise_uncaught_exception(exc)
  File "C:\Users\kt841\Documents\SocialMedia\venv\Lib\site-packages\rest_framework\views.py", line 480, in raise_uncaught_exception
    raise exc
  File "C:\Users\kt841\Documents\SocialMedia\venv\Lib\site-packages\rest_framework\views.py", line 506, in dispatch
    response = handler(request, *args, **kwargs)
               ^^^^^^^^^^^^^^^^^^^^^^^^^^^^^^^^^
  File "C:\Users\kt841\Documents\SocialMedia\social_media\post\views.py", line 24, in get
    x = Post.objects.get('user_id')
        ^^^^^^^^^^^^^^^^^^^^^^^^^^^
  File "C:\Users\kt841\Documents\SocialMedia\venv\Lib\site-packages\django\db\models\manager.py", line 87, in manager_method
    return getattr(self.get_queryset(), name)(*args, **kwargs)
           ^^^^^^^^^^^^^^^^^^^^^^^^^^^^^^^^^^^^^^^^^^^^^^^^^^^
  File "C:\Users\kt841\Documents\SocialMedia\venv\Lib\site-packages\django\db\models\query.py", line 623, in get
    clone = self._chain() if self.query.combinator else self.filter(*args, **kwargs)
                                                        ^^^^^^^^^^^^^^^^^^^^^^^^^^^^
  File "C:\Users\kt841\Documents\SocialMedia\venv\Lib\site-packages\django\db\models\query.py", line 1436, in filter
    return self._filter_or_exclude(False, args, kwargs)
           ^^^^^^^^^^^^^^^^^^^^^^^^^^^^^^^^^^^^^^^^^^^^
  File "C:\Users\kt841\Documents\SocialMedia\venv\Lib\site-packages\django\db\models\query.py", line 1454, in _filter_or_exclude
    clone._filter_or_exclude_inplace(negate, args, kwargs)
  File "C:\Users\kt841\Documents\SocialMedia\venv\Lib\site-packages\django\db\models\query.py", line 1461, in _filter_or_exclude_inplace
    self._query.add_q(Q(*args, **kwargs))
  File "C:\Users\kt841\Documents\SocialMedia\venv\Lib\site-packages\django\db\models\sql\query.py", line 1545, in add_q
    clause, _ = self._add_q(q_object, self.used_aliases)
                ^^^^^^^^^^^^^^^^^^^^^^^^^^^^^^^^^^^^^^^^
  File "C:\Users\kt841\Documents\SocialMedia\venv\Lib\site-packages\django\db\models\sql\query.py", line 1576, in _add_q
    child_clause, needed_inner = self.build_filter(
                                 ^^^^^^^^^^^^^^^^^^
  File "C:\Users\kt841\Documents\SocialMedia\venv\Lib\site-packages\django\db\models\sql\query.py", line 1423, in build_filter
    arg, value = filter_expr
    ^^^^^^^^^^
ValueError: too many values to unpack (expected 2)
"GET /post/ HTTP/1.1" 500 130233
C:\Users\kt841\Documents\SocialMedia\social_media\post\views.py changed, reloading.
Watching for file changes with StatReloader
C:\Users\kt841\Documents\SocialMedia\social_media\post\views.py changed, reloading.
Watching for file changes with StatReloader
C:\Users\kt841\Documents\SocialMedia\social_media\post\views.py changed, reloading.
Watching for file changes with StatReloader
C:\Users\kt841\Documents\SocialMedia\social_media\post\views.py changed, reloading.
Watching for file changes with StatReloader
C:\Users\kt841\Documents\SocialMedia\social_media\post\views.py changed, reloading.
Watching for file changes with StatReloader
C:\Users\kt841\Documents\SocialMedia\social_media\post\views.py changed, reloading.
Watching for file changes with StatReloader
C:\Users\kt841\Documents\SocialMedia\social_media\post\views.py changed, reloading.
Watching for file changes with StatReloader
"GET /post/ HTTP/1.1" 200 629
C:\Users\kt841\Documents\SocialMedia\social_media\post\views.py changed, reloading.
Watching for file changes with StatReloader
C:\Users\kt841\Documents\SocialMedia\social_media\post\views.py changed, reloading.
Watching for file changes with StatReloader
C:\Users\kt841\Documents\SocialMedia\social_media\post\views.py changed, reloading.
Watching for file changes with StatReloader
C:\Users\kt841\Documents\SocialMedia\social_media\post\views.py changed, reloading.
Watching for file changes with StatReloader
C:\Users\kt841\Documents\SocialMedia\social_media\post\views.py changed, reloading.
Watching for file changes with StatReloader
Internal Server Error: /post/
Traceback (most recent call last):
  File "C:\Users\kt841\Documents\SocialMedia\venv\Lib\site-packages\django\core\handlers\exception.py", line 55, in inner
    response = get_response(request)
               ^^^^^^^^^^^^^^^^^^^^^
  File "C:\Users\kt841\Documents\SocialMedia\venv\Lib\site-packages\django\core\handlers\base.py", line 197, in _get_response
    response = wrapped_callback(request, *callback_args, **callback_kwargs)
               ^^^^^^^^^^^^^^^^^^^^^^^^^^^^^^^^^^^^^^^^^^^^^^^^^^^^^^^^^^^^
  File "C:\Users\kt841\Documents\SocialMedia\venv\Lib\site-packages\django\views\decorators\csrf.py", line 56, in wrapper_view
    return view_func(*args, **kwargs)
           ^^^^^^^^^^^^^^^^^^^^^^^^^^
  File "C:\Users\kt841\Documents\SocialMedia\venv\Lib\site-packages\django\views\generic\base.py", line 104, in view
    return self.dispatch(request, *args, **kwargs)
           ^^^^^^^^^^^^^^^^^^^^^^^^^^^^^^^^^^^^^^^
  File "C:\Users\kt841\Documents\SocialMedia\venv\Lib\site-packages\rest_framework\views.py", line 509, in dispatch
    response = self.handle_exception(exc)
               ^^^^^^^^^^^^^^^^^^^^^^^^^^
  File "C:\Users\kt841\Documents\SocialMedia\venv\Lib\site-packages\rest_framework\views.py", line 469, in handle_exception
    self.raise_uncaught_exception(exc)
  File "C:\Users\kt841\Documents\SocialMedia\venv\Lib\site-packages\rest_framework\views.py", line 480, in raise_uncaught_exception
    raise exc
  File "C:\Users\kt841\Documents\SocialMedia\venv\Lib\site-packages\rest_framework\views.py", line 506, in dispatch
    response = handler(request, *args, **kwargs)
               ^^^^^^^^^^^^^^^^^^^^^^^^^^^^^^^^^
  File "C:\Users\kt841\Documents\SocialMedia\social_media\post\views.py", line 24, in get
    x = Post.objects.get(post_id = "47768907-bae8-4784-b40d-e8de3784f5f0")
        ^^^^^^^^^^^^^^^^^^^^^^^^^^^^^^^^^^^^^^^^^^^^^^^^^^^^^^^^^^^^^^^^^^
  File "C:\Users\kt841\Documents\SocialMedia\venv\Lib\site-packages\django\db\models\manager.py", line 87, in manager_method
    return getattr(self.get_queryset(), name)(*args, **kwargs)
           ^^^^^^^^^^^^^^^^^^^^^^^^^^^^^^^^^^^^^^^^^^^^^^^^^^^
  File "C:\Users\kt841\Documents\SocialMedia\venv\Lib\site-packages\django\db\models\query.py", line 623, in get
    clone = self._chain() if self.query.combinator else self.filter(*args, **kwargs)
                                                        ^^^^^^^^^^^^^^^^^^^^^^^^^^^^
  File "C:\Users\kt841\Documents\SocialMedia\venv\Lib\site-packages\django\db\models\query.py", line 1436, in filter
    return self._filter_or_exclude(False, args, kwargs)
           ^^^^^^^^^^^^^^^^^^^^^^^^^^^^^^^^^^^^^^^^^^^^
  File "C:\Users\kt841\Documents\SocialMedia\venv\Lib\site-packages\django\db\models\query.py", line 1454, in _filter_or_exclude
    clone._filter_or_exclude_inplace(negate, args, kwargs)
  File "C:\Users\kt841\Documents\SocialMedia\venv\Lib\site-packages\django\db\models\query.py", line 1461, in _filter_or_exclude_inplace
    self._query.add_q(Q(*args, **kwargs))
  File "C:\Users\kt841\Documents\SocialMedia\venv\Lib\site-packages\django\db\models\sql\query.py", line 1545, in add_q
    clause, _ = self._add_q(q_object, self.used_aliases)
                ^^^^^^^^^^^^^^^^^^^^^^^^^^^^^^^^^^^^^^^^
  File "C:\Users\kt841\Documents\SocialMedia\venv\Lib\site-packages\django\db\models\sql\query.py", line 1576, in _add_q
    child_clause, needed_inner = self.build_filter(
                                 ^^^^^^^^^^^^^^^^^^
  File "C:\Users\kt841\Documents\SocialMedia\venv\Lib\site-packages\django\db\models\sql\query.py", line 1426, in build_filter
    lookups, parts, reffed_expression = self.solve_lookup_type(arg, summarize)
                                        ^^^^^^^^^^^^^^^^^^^^^^^^^^^^^^^^^^^^^^
  File "C:\Users\kt841\Documents\SocialMedia\venv\Lib\site-packages\django\db\models\sql\query.py", line 1236, in solve_lookup_type
    _, field, _, lookup_parts = self.names_to_path(lookup_splitted, self.get_meta())
                                ^^^^^^^^^^^^^^^^^^^^^^^^^^^^^^^^^^^^^^^^^^^^^^^^^^^^
  File "C:\Users\kt841\Documents\SocialMedia\venv\Lib\site-packages\django\db\models\sql\query.py", line 1724, in names_to_path
    raise FieldError(
django.core.exceptions.FieldError: Cannot resolve keyword 'post_id' into field. Choices are: comment, created_at, id, like, likes, modified_at, text, user, user_id
"GET /post/ HTTP/1.1" 500 142579
C:\Users\kt841\Documents\SocialMedia\social_media\post\views.py changed, reloading.
Watching for file changes with StatReloader
"GET /post/ HTTP/1.1" 200 629
C:\Users\kt841\Documents\SocialMedia\social_media\post\views.py changed, reloading.
Watching for file changes with StatReloader
C:\Users\kt841\Documents\SocialMedia\social_media\post\views.py changed, reloading.
Watching for file changes with StatReloader
Internal Server Error: /post/
Traceback (most recent call last):
  File "C:\Users\kt841\Documents\SocialMedia\venv\Lib\site-packages\django\core\handlers\exception.py", line 55, in inner
    response = get_response(request)
               ^^^^^^^^^^^^^^^^^^^^^
  File "C:\Users\kt841\Documents\SocialMedia\venv\Lib\site-packages\django\core\handlers\base.py", line 197, in _get_response
    response = wrapped_callback(request, *callback_args, **callback_kwargs)
               ^^^^^^^^^^^^^^^^^^^^^^^^^^^^^^^^^^^^^^^^^^^^^^^^^^^^^^^^^^^^
  File "C:\Users\kt841\Documents\SocialMedia\venv\Lib\site-packages\django\views\decorators\csrf.py", line 56, in wrapper_view
    return view_func(*args, **kwargs)
           ^^^^^^^^^^^^^^^^^^^^^^^^^^
  File "C:\Users\kt841\Documents\SocialMedia\venv\Lib\site-packages\django\views\generic\base.py", line 104, in view
    return self.dispatch(request, *args, **kwargs)
           ^^^^^^^^^^^^^^^^^^^^^^^^^^^^^^^^^^^^^^^
  File "C:\Users\kt841\Documents\SocialMedia\venv\Lib\site-packages\rest_framework\views.py", line 509, in dispatch
    response = self.handle_exception(exc)
               ^^^^^^^^^^^^^^^^^^^^^^^^^^
  File "C:\Users\kt841\Documents\SocialMedia\venv\Lib\site-packages\rest_framework\views.py", line 469, in handle_exception
    self.raise_uncaught_exception(exc)
  File "C:\Users\kt841\Documents\SocialMedia\venv\Lib\site-packages\rest_framework\views.py", line 480, in raise_uncaught_exception
    raise exc
  File "C:\Users\kt841\Documents\SocialMedia\venv\Lib\site-packages\rest_framework\views.py", line 506, in dispatch
    response = handler(request, *args, **kwargs)
               ^^^^^^^^^^^^^^^^^^^^^^^^^^^^^^^^^
  File "C:\Users\kt841\Documents\SocialMedia\social_media\post\views.py", line 24, in get
    x = Post.objects.get(user =1)
        ^^^^^^^^^^^^^^^^^^^^^^^^^
  File "C:\Users\kt841\Documents\SocialMedia\venv\Lib\site-packages\django\db\models\manager.py", line 87, in manager_method
    return getattr(self.get_queryset(), name)(*args, **kwargs)
           ^^^^^^^^^^^^^^^^^^^^^^^^^^^^^^^^^^^^^^^^^^^^^^^^^^^
  File "C:\Users\kt841\Documents\SocialMedia\venv\Lib\site-packages\django\db\models\query.py", line 640, in get
    raise self.model.MultipleObjectsReturned(
post.models.Post.MultipleObjectsReturned: get() returned more than one Post -- it returned 4!
"GET /post/ HTTP/1.1" 500 101445
C:\Users\kt841\Documents\SocialMedia\social_media\post\views.py changed, reloading.
Watching for file changes with StatReloader
Internal Server Error: /post/
Traceback (most recent call last):
  File "C:\Users\kt841\Documents\SocialMedia\venv\Lib\site-packages\django\core\handlers\exception.py", line 55, in inner
    response = get_response(request)
               ^^^^^^^^^^^^^^^^^^^^^
  File "C:\Users\kt841\Documents\SocialMedia\venv\Lib\site-packages\django\core\handlers\base.py", line 197, in _get_response
    response = wrapped_callback(request, *callback_args, **callback_kwargs)
               ^^^^^^^^^^^^^^^^^^^^^^^^^^^^^^^^^^^^^^^^^^^^^^^^^^^^^^^^^^^^
  File "C:\Users\kt841\Documents\SocialMedia\venv\Lib\site-packages\django\views\decorators\csrf.py", line 56, in wrapper_view
    return view_func(*args, **kwargs)
           ^^^^^^^^^^^^^^^^^^^^^^^^^^
  File "C:\Users\kt841\Documents\SocialMedia\venv\Lib\site-packages\django\views\generic\base.py", line 104, in view
    return self.dispatch(request, *args, **kwargs)
           ^^^^^^^^^^^^^^^^^^^^^^^^^^^^^^^^^^^^^^^
  File "C:\Users\kt841\Documents\SocialMedia\venv\Lib\site-packages\rest_framework\views.py", line 509, in dispatch
    response = self.handle_exception(exc)
               ^^^^^^^^^^^^^^^^^^^^^^^^^^
  File "C:\Users\kt841\Documents\SocialMedia\venv\Lib\site-packages\rest_framework\views.py", line 469, in handle_exception
    self.raise_uncaught_exception(exc)
  File "C:\Users\kt841\Documents\SocialMedia\venv\Lib\site-packages\rest_framework\views.py", line 480, in raise_uncaught_exception
    raise exc
  File "C:\Users\kt841\Documents\SocialMedia\venv\Lib\site-packages\rest_framework\views.py", line 506, in dispatch
    response = handler(request, *args, **kwargs)
               ^^^^^^^^^^^^^^^^^^^^^^^^^^^^^^^^^
  File "C:\Users\kt841\Documents\SocialMedia\social_media\post\views.py", line 24, in get
    x = Post.objects.get(user =2)
        ^^^^^^^^^^^^^^^^^^^^^^^^^
  File "C:\Users\kt841\Documents\SocialMedia\venv\Lib\site-packages\django\db\models\manager.py", line 87, in manager_method
    return getattr(self.get_queryset(), name)(*args, **kwargs)
           ^^^^^^^^^^^^^^^^^^^^^^^^^^^^^^^^^^^^^^^^^^^^^^^^^^^
  File "C:\Users\kt841\Documents\SocialMedia\venv\Lib\site-packages\django\db\models\query.py", line 637, in get
    raise self.model.DoesNotExist(
post.models.Post.DoesNotExist: Post matching query does not exist.
"GET /post/ HTTP/1.1" 500 100966
C:\Users\kt841\Documents\SocialMedia\social_media\post\views.py changed, reloading.
Watching for file changes with StatReloader
Internal Server Error: /post/
Traceback (most recent call last):
  File "C:\Users\kt841\Documents\SocialMedia\venv\Lib\site-packages\django\core\handlers\exception.py", line 55, in inner
    response = get_response(request)
               ^^^^^^^^^^^^^^^^^^^^^
  File "C:\Users\kt841\Documents\SocialMedia\venv\Lib\site-packages\django\core\handlers\base.py", line 197, in _get_response
    response = wrapped_callback(request, *callback_args, **callback_kwargs)
               ^^^^^^^^^^^^^^^^^^^^^^^^^^^^^^^^^^^^^^^^^^^^^^^^^^^^^^^^^^^^
  File "C:\Users\kt841\Documents\SocialMedia\venv\Lib\site-packages\django\views\decorators\csrf.py", line 56, in wrapper_view
    return view_func(*args, **kwargs)
           ^^^^^^^^^^^^^^^^^^^^^^^^^^
  File "C:\Users\kt841\Documents\SocialMedia\venv\Lib\site-packages\django\views\generic\base.py", line 104, in view
    return self.dispatch(request, *args, **kwargs)
           ^^^^^^^^^^^^^^^^^^^^^^^^^^^^^^^^^^^^^^^
  File "C:\Users\kt841\Documents\SocialMedia\venv\Lib\site-packages\rest_framework\views.py", line 509, in dispatch
    response = self.handle_exception(exc)
               ^^^^^^^^^^^^^^^^^^^^^^^^^^
  File "C:\Users\kt841\Documents\SocialMedia\venv\Lib\site-packages\rest_framework\views.py", line 469, in handle_exception
    self.raise_uncaught_exception(exc)
  File "C:\Users\kt841\Documents\SocialMedia\venv\Lib\site-packages\rest_framework\views.py", line 480, in raise_uncaught_exception
    raise exc
  File "C:\Users\kt841\Documents\SocialMedia\venv\Lib\site-packages\rest_framework\views.py", line 506, in dispatch
    response = handler(request, *args, **kwargs)
               ^^^^^^^^^^^^^^^^^^^^^^^^^^^^^^^^^
  File "C:\Users\kt841\Documents\SocialMedia\social_media\post\views.py", line 24, in get
    x = Post.objects.get(user =1)
        ^^^^^^^^^^^^^^^^^^^^^^^^^
  File "C:\Users\kt841\Documents\SocialMedia\venv\Lib\site-packages\django\db\models\manager.py", line 87, in manager_method
    return getattr(self.get_queryset(), name)(*args, **kwargs)
           ^^^^^^^^^^^^^^^^^^^^^^^^^^^^^^^^^^^^^^^^^^^^^^^^^^^
  File "C:\Users\kt841\Documents\SocialMedia\venv\Lib\site-packages\django\db\models\query.py", line 640, in get
    raise self.model.MultipleObjectsReturned(
post.models.Post.MultipleObjectsReturned: get() returned more than one Post -- it returned 4!
"GET /post/ HTTP/1.1" 500 101445
C:\Users\kt841\Documents\SocialMedia\social_media\post\views.py changed, reloading.
Watching for file changes with StatReloader
Unauthorized: /post/
"GET /post/ HTTP/1.1" 401 183
"POST /api/token/refresh/ HTTP/1.1" 200 241
Internal Server Error: /post/
Traceback (most recent call last):
  File "C:\Users\kt841\Documents\SocialMedia\venv\Lib\site-packages\django\core\handlers\exception.py", line 55, in inner
    response = get_response(request)
               ^^^^^^^^^^^^^^^^^^^^^
  File "C:\Users\kt841\Documents\SocialMedia\venv\Lib\site-packages\django\core\handlers\base.py", line 197, in _get_response
    response = wrapped_callback(request, *callback_args, **callback_kwargs)
               ^^^^^^^^^^^^^^^^^^^^^^^^^^^^^^^^^^^^^^^^^^^^^^^^^^^^^^^^^^^^
  File "C:\Users\kt841\Documents\SocialMedia\venv\Lib\site-packages\django\views\decorators\csrf.py", line 56, in wrapper_view
    return view_func(*args, **kwargs)
           ^^^^^^^^^^^^^^^^^^^^^^^^^^
  File "C:\Users\kt841\Documents\SocialMedia\venv\Lib\site-packages\django\views\generic\base.py", line 104, in view
    return self.dispatch(request, *args, **kwargs)
           ^^^^^^^^^^^^^^^^^^^^^^^^^^^^^^^^^^^^^^^
  File "C:\Users\kt841\Documents\SocialMedia\venv\Lib\site-packages\rest_framework\views.py", line 509, in dispatch
    response = self.handle_exception(exc)
               ^^^^^^^^^^^^^^^^^^^^^^^^^^
  File "C:\Users\kt841\Documents\SocialMedia\venv\Lib\site-packages\rest_framework\views.py", line 469, in handle_exception
    self.raise_uncaught_exception(exc)
  File "C:\Users\kt841\Documents\SocialMedia\venv\Lib\site-packages\rest_framework\views.py", line 480, in raise_uncaught_exception
    raise exc
  File "C:\Users\kt841\Documents\SocialMedia\venv\Lib\site-packages\rest_framework\views.py", line 506, in dispatch
    response = handler(request, *args, **kwargs)
               ^^^^^^^^^^^^^^^^^^^^^^^^^^^^^^^^^
  File "C:\Users\kt841\Documents\SocialMedia\social_media\post\views.py", line 24, in get
    x = Post.objects.flter(user =1)
        ^^^^^^^^^^^^^^^^^^
AttributeError: 'Manager' object has no attribute 'flter'
"GET /post/ HTTP/1.1" 500 92182
C:\Users\kt841\Documents\SocialMedia\social_media\post\views.py changed, reloading.
Watching for file changes with StatReloader
"GET /post/ HTTP/1.1" 200 629
C:\Users\kt841\Documents\SocialMedia\social_media\post\views.py changed, reloading.
Watching for file changes with StatReloader
"GET /post/ HTTP/1.1" 200 629
C:\Users\kt841\Documents\SocialMedia\social_media\post\views.py changed, reloading.
Watching for file changes with StatReloader
"GET /users/ HTTP/1.1" 200 949
"GET /post/ HTTP/1.1" 200 629
Unauthorized: /post/
"POST /post/ HTTP/1.1" 401 58
"POST /api/token/ HTTP/1.1" 200 483
Unauthorized: /post/
"POST /post/ HTTP/1.1" 401 58
"POST /user/signup/ HTTP/1.1" 200 186
"POST /api/token/ HTTP/1.1" 200 486
"GET /user/profile HTTP/1.1" 301 0
"GET /user/profile/ HTTP/1.1" 200 146
"GET /post/ HTTP/1.1" 200 629
Unauthorized: /post/
"POST /post/ HTTP/1.1" 401 58
Unauthorized: /post/
"POST /post/ HTTP/1.1" 401 58
"POST /api/token/ HTTP/1.1" 200 483
"GET /user/profile HTTP/1.1" 301 0
"GET /user/profile/ HTTP/1.1" 200 144
Method Not Allowed: /post/comment/
"POST /post/comment/ HTTP/1.1" 405 41
Unauthorized: /post/
"POST /post/ HTTP/1.1" 401 58
C:\Users\kt841\Documents\SocialMedia\social_media\social_media\settings.py changed, reloading.
Watching for file changes with StatReloader
Unauthorized: /post/
"POST /post/ HTTP/1.1" 401 58
C:\Users\kt841\Documents\SocialMedia\social_media\social_media\settings.py changed, reloading.
Watching for file changes with StatReloader
Unauthorized: /post/
"POST /post/ HTTP/1.1" 401 58
C:\Users\kt841\Documents\SocialMedia\social_media\social_media\settings.py changed, reloading.
Watching for file changes with StatReloader
C:\Users\kt841\Documents\SocialMedia\social_media\social_media\settings.py changed, reloading.
Watching for file changes with StatReloader
"POST /api/token/ HTTP/1.1" 200 483
"GET /user/profile HTTP/1.1" 301 0
"GET /user/profile/ HTTP/1.1" 200 144
Unauthorized: /post/
"POST /post/ HTTP/1.1" 401 58
C:\Users\kt841\Documents\SocialMedia\social_media\social_media\settings.py changed, reloading.
Watching for file changes with StatReloader
"POST /api/token/refresh/ HTTP/1.1" 200 241
"POST /api/token/refresh/ HTTP/1.1" 200 241
Unauthorized: /post/
"POST /post/ HTTP/1.1" 401 58
"GET /users/ HTTP/1.1" 200 1055
"POST /post/ HTTP/1.1" 200 229
"POST /api/token/ HTTP/1.1" 200 486
"GET /user/profile HTTP/1.1" 301 0
"GET /user/profile/ HTTP/1.1" 200 146
"POST /post/ HTTP/1.1" 200 229
"GET /post/ HTTP/1.1" 200 961
Unsupported Media Type: /post/like/
"POST /post/like/ HTTP/1.1" 415 62
C:\Users\kt841\Documents\SocialMedia\social_media\post\views.py changed, reloading.
Watching for file changes with StatReloader
Unsupported Media Type: /post/like/
"POST /post/like/ HTTP/1.1" 415 62
Unsupported Media Type: /post/like/
"POST /post/like/ HTTP/1.1" 415 62
Unsupported Media Type: /post/like/
"POST /post/like/ HTTP/1.1" 415 62
"POST /post/like/ HTTP/1.1" 200 63
"GET /post/comment/ HTTP/1.1" 200 2
Method Not Allowed: /post/comment/
"POST /post/comment/ HTTP/1.1" 405 41
C:\Users\kt841\Documents\SocialMedia\social_media\post\views.py changed, reloading.
Watching for file changes with StatReloader
C:\Users\kt841\Documents\SocialMedia\social_media\post\views.py changed, reloading.
Watching for file changes with StatReloader
Method Not Allowed: /post/comment/
"POST /post/comment/ HTTP/1.1" 405 41
C:\Users\kt841\Documents\SocialMedia\social_media\post\views.py changed, reloading.
Watching for file changes with StatReloader
C:\Users\kt841\Documents\SocialMedia\social_media\post\views.py changed, reloading.
Watching for file changes with StatReloader
Unauthorized: /post/comment/
"POST /post/comment/ HTTP/1.1" 401 183
"POST /api/token/refresh/ HTTP/1.1" 200 242
Internal Server Error: /post/comment/
Traceback (most recent call last):
  File "C:\Users\kt841\Documents\SocialMedia\venv\Lib\site-packages\django\core\handlers\exception.py", line 55, in inner
    response = get_response(request)
               ^^^^^^^^^^^^^^^^^^^^^
  File "C:\Users\kt841\Documents\SocialMedia\venv\Lib\site-packages\django\core\handlers\base.py", line 197, in _get_response
    response = wrapped_callback(request, *callback_args, **callback_kwargs)
               ^^^^^^^^^^^^^^^^^^^^^^^^^^^^^^^^^^^^^^^^^^^^^^^^^^^^^^^^^^^^
  File "C:\Users\kt841\Documents\SocialMedia\venv\Lib\site-packages\django\views\decorators\csrf.py", line 56, in wrapper_view
    return view_func(*args, **kwargs)
           ^^^^^^^^^^^^^^^^^^^^^^^^^^
  File "C:\Users\kt841\Documents\SocialMedia\venv\Lib\site-packages\django\views\generic\base.py", line 104, in view
    return self.dispatch(request, *args, **kwargs)
           ^^^^^^^^^^^^^^^^^^^^^^^^^^^^^^^^^^^^^^^
  File "C:\Users\kt841\Documents\SocialMedia\venv\Lib\site-packages\rest_framework\views.py", line 509, in dispatch
    response = self.handle_exception(exc)
               ^^^^^^^^^^^^^^^^^^^^^^^^^^
  File "C:\Users\kt841\Documents\SocialMedia\venv\Lib\site-packages\rest_framework\views.py", line 469, in handle_exception
    self.raise_uncaught_exception(exc)
  File "C:\Users\kt841\Documents\SocialMedia\venv\Lib\site-packages\rest_framework\views.py", line 480, in raise_uncaught_exception
    raise exc
  File "C:\Users\kt841\Documents\SocialMedia\venv\Lib\site-packages\rest_framework\views.py", line 506, in dispatch
    response = handler(request, *args, **kwargs)
               ^^^^^^^^^^^^^^^^^^^^^^^^^^^^^^^^^
  File "C:\Users\kt841\Documents\SocialMedia\social_media\post\views.py", line 160, in post
    comment = Comment(user=user_id, post=post_id, text=text)
              ^^^^^^^^^^^^^^^^^^^^^^^^^^^^^^^^^^^^^^^^^^^^^^
  File "C:\Users\kt841\Documents\SocialMedia\venv\Lib\site-packages\django\db\models\base.py", line 543, in __init__
    _setattr(self, field.name, rel_obj)
  File "C:\Users\kt841\Documents\SocialMedia\venv\Lib\site-packages\django\db\models\fields\related_descriptors.py", line 266, in __set__
    raise ValueError(
ValueError: Cannot assign "25": "Comment.user" must be a "User" instance.
"POST /post/comment/ HTTP/1.1" 500 103520
C:\Users\kt841\Documents\SocialMedia\social_media\post\views.py changed, reloading.
Watching for file changes with StatReloader
C:\Users\kt841\Documents\SocialMedia\social_media\post\views.py changed, reloading.
Watching for file changes with StatReloader
C:\Users\kt841\Documents\SocialMedia\social_media\post\views.py changed, reloading.
Watching for file changes with StatReloader
C:\Users\kt841\Documents\SocialMedia\social_media\post\views.py changed, reloading.
Watching for file changes with StatReloader
Internal Server Error: /post/comment/
Traceback (most recent call last):
  File "C:\Users\kt841\Documents\SocialMedia\venv\Lib\site-packages\django\core\handlers\exception.py", line 55, in inner
    response = get_response(request)
               ^^^^^^^^^^^^^^^^^^^^^
  File "C:\Users\kt841\Documents\SocialMedia\venv\Lib\site-packages\django\core\handlers\base.py", line 197, in _get_response
    response = wrapped_callback(request, *callback_args, **callback_kwargs)
               ^^^^^^^^^^^^^^^^^^^^^^^^^^^^^^^^^^^^^^^^^^^^^^^^^^^^^^^^^^^^
  File "C:\Users\kt841\Documents\SocialMedia\venv\Lib\site-packages\django\views\decorators\csrf.py", line 56, in wrapper_view
    return view_func(*args, **kwargs)
           ^^^^^^^^^^^^^^^^^^^^^^^^^^
  File "C:\Users\kt841\Documents\SocialMedia\venv\Lib\site-packages\django\views\generic\base.py", line 104, in view
    return self.dispatch(request, *args, **kwargs)
           ^^^^^^^^^^^^^^^^^^^^^^^^^^^^^^^^^^^^^^^
  File "C:\Users\kt841\Documents\SocialMedia\venv\Lib\site-packages\rest_framework\views.py", line 509, in dispatch
    response = self.handle_exception(exc)
               ^^^^^^^^^^^^^^^^^^^^^^^^^^
  File "C:\Users\kt841\Documents\SocialMedia\venv\Lib\site-packages\rest_framework\views.py", line 469, in handle_exception
    self.raise_uncaught_exception(exc)
  File "C:\Users\kt841\Documents\SocialMedia\venv\Lib\site-packages\rest_framework\views.py", line 480, in raise_uncaught_exception
    raise exc
  File "C:\Users\kt841\Documents\SocialMedia\venv\Lib\site-packages\rest_framework\views.py", line 506, in dispatch
    response = handler(request, *args, **kwargs)
               ^^^^^^^^^^^^^^^^^^^^^^^^^^^^^^^^^
  File "C:\Users\kt841\Documents\SocialMedia\social_media\post\views.py", line 160, in post
    comment = Comment(user=user_id, post=post_id, text=text)
              ^^^^^^^^^^^^^^^^^^^^^^^^^^^^^^^^^^^^^^^^^^^^^^
  File "C:\Users\kt841\Documents\SocialMedia\venv\Lib\site-packages\django\db\models\base.py", line 543, in __init__
    _setattr(self, field.name, rel_obj)
  File "C:\Users\kt841\Documents\SocialMedia\venv\Lib\site-packages\django\db\models\fields\related_descriptors.py", line 266, in __set__
    raise ValueError(
ValueError: Cannot assign "25": "Comment.user" must be a "User" instance.
"POST /post/comment/ HTTP/1.1" 500 103512
C:\Users\kt841\Documents\SocialMedia\social_media\post\views.py changed, reloading.
Watching for file changes with StatReloader
C:\Users\kt841\Documents\SocialMedia\social_media\post\views.py changed, reloading.
Watching for file changes with StatReloader
C:\Users\kt841\Documents\SocialMedia\social_media\post\views.py changed, reloading.
Watching for file changes with StatReloader
Unauthorized: /post/comment/
"POST /post/comment/ HTTP/1.1" 401 183
"POST /api/token/refresh/ HTTP/1.1" 200 242
Internal Server Error: /post/comment/
Traceback (most recent call last):
  File "C:\Users\kt841\Documents\SocialMedia\venv\Lib\site-packages\django\core\handlers\exception.py", line 55, in inner
    response = get_response(request)
               ^^^^^^^^^^^^^^^^^^^^^
  File "C:\Users\kt841\Documents\SocialMedia\venv\Lib\site-packages\django\core\handlers\base.py", line 197, in _get_response
    response = wrapped_callback(request, *callback_args, **callback_kwargs)
               ^^^^^^^^^^^^^^^^^^^^^^^^^^^^^^^^^^^^^^^^^^^^^^^^^^^^^^^^^^^^
  File "C:\Users\kt841\Documents\SocialMedia\venv\Lib\site-packages\django\views\decorators\csrf.py", line 56, in wrapper_view
    return view_func(*args, **kwargs)
           ^^^^^^^^^^^^^^^^^^^^^^^^^^
  File "C:\Users\kt841\Documents\SocialMedia\venv\Lib\site-packages\django\views\generic\base.py", line 104, in view
    return self.dispatch(request, *args, **kwargs)
           ^^^^^^^^^^^^^^^^^^^^^^^^^^^^^^^^^^^^^^^
  File "C:\Users\kt841\Documents\SocialMedia\venv\Lib\site-packages\rest_framework\views.py", line 509, in dispatch
    response = self.handle_exception(exc)
               ^^^^^^^^^^^^^^^^^^^^^^^^^^
  File "C:\Users\kt841\Documents\SocialMedia\venv\Lib\site-packages\rest_framework\views.py", line 469, in handle_exception
    self.raise_uncaught_exception(exc)
  File "C:\Users\kt841\Documents\SocialMedia\venv\Lib\site-packages\rest_framework\views.py", line 480, in raise_uncaught_exception
    raise exc
  File "C:\Users\kt841\Documents\SocialMedia\venv\Lib\site-packages\rest_framework\views.py", line 506, in dispatch
    response = handler(request, *args, **kwargs)
               ^^^^^^^^^^^^^^^^^^^^^^^^^^^^^^^^^
  File "C:\Users\kt841\Documents\SocialMedia\social_media\post\views.py", line 159, in post
    comment = Comment(post=post_id, text=text)
              ^^^^^^^^^^^^^^^^^^^^^^^^^^^^^^^^
  File "C:\Users\kt841\Documents\SocialMedia\venv\Lib\site-packages\django\db\models\base.py", line 543, in __init__
    _setattr(self, field.name, rel_obj)
  File "C:\Users\kt841\Documents\SocialMedia\venv\Lib\site-packages\django\db\models\fields\related_descriptors.py", line 266, in __set__
    raise ValueError(
ValueError: Cannot assign "'47768907-bae8-4784-b40d-e8de3784f5f0'": "Comment.post" must be a "Post" instance.
"POST /post/comment/ HTTP/1.1" 500 103604
C:\Users\kt841\Documents\SocialMedia\social_media\post\views.py changed, reloading.
Watching for file changes with StatReloader
"GET /post/comment/ HTTP/1.1" 200 2
Internal Server Error: /post/comment/
Traceback (most recent call last):
  File "C:\Users\kt841\Documents\SocialMedia\venv\Lib\site-packages\django\core\handlers\exception.py", line 55, in inner
    response = get_response(request)
               ^^^^^^^^^^^^^^^^^^^^^
  File "C:\Users\kt841\Documents\SocialMedia\venv\Lib\site-packages\django\core\handlers\base.py", line 197, in _get_response
    response = wrapped_callback(request, *callback_args, **callback_kwargs)
               ^^^^^^^^^^^^^^^^^^^^^^^^^^^^^^^^^^^^^^^^^^^^^^^^^^^^^^^^^^^^
  File "C:\Users\kt841\Documents\SocialMedia\venv\Lib\site-packages\django\views\decorators\csrf.py", line 56, in wrapper_view
    return view_func(*args, **kwargs)
           ^^^^^^^^^^^^^^^^^^^^^^^^^^
  File "C:\Users\kt841\Documents\SocialMedia\venv\Lib\site-packages\django\views\generic\base.py", line 104, in view
    return self.dispatch(request, *args, **kwargs)
           ^^^^^^^^^^^^^^^^^^^^^^^^^^^^^^^^^^^^^^^
  File "C:\Users\kt841\Documents\SocialMedia\venv\Lib\site-packages\rest_framework\views.py", line 509, in dispatch
    response = self.handle_exception(exc)
               ^^^^^^^^^^^^^^^^^^^^^^^^^^
  File "C:\Users\kt841\Documents\SocialMedia\venv\Lib\site-packages\rest_framework\views.py", line 469, in handle_exception
    self.raise_uncaught_exception(exc)
  File "C:\Users\kt841\Documents\SocialMedia\venv\Lib\site-packages\rest_framework\views.py", line 480, in raise_uncaught_exception
    raise exc
  File "C:\Users\kt841\Documents\SocialMedia\venv\Lib\site-packages\rest_framework\views.py", line 506, in dispatch
    response = handler(request, *args, **kwargs)
               ^^^^^^^^^^^^^^^^^^^^^^^^^^^^^^^^^
  File "C:\Users\kt841\Documents\SocialMedia\social_media\post\views.py", line 160, in post
    comment = Comment(user=user_id, post=post_id, text=text)
              ^^^^^^^^^^^^^^^^^^^^^^^^^^^^^^^^^^^^^^^^^^^^^^
  File "C:\Users\kt841\Documents\SocialMedia\venv\Lib\site-packages\django\db\models\base.py", line 543, in __init__
    _setattr(self, field.name, rel_obj)
  File "C:\Users\kt841\Documents\SocialMedia\venv\Lib\site-packages\django\db\models\fields\related_descriptors.py", line 266, in __set__
    raise ValueError(
ValueError: Cannot assign "1": "Comment.user" must be a "User" instance.
"POST /post/comment/ HTTP/1.1" 500 103503
Internal Server Error: /post/comment/
Traceback (most recent call last):
  File "C:\Users\kt841\Documents\SocialMedia\venv\Lib\site-packages\django\core\handlers\exception.py", line 55, in inner
    response = get_response(request)
               ^^^^^^^^^^^^^^^^^^^^^
  File "C:\Users\kt841\Documents\SocialMedia\venv\Lib\site-packages\django\core\handlers\base.py", line 197, in _get_response
    response = wrapped_callback(request, *callback_args, **callback_kwargs)
               ^^^^^^^^^^^^^^^^^^^^^^^^^^^^^^^^^^^^^^^^^^^^^^^^^^^^^^^^^^^^
  File "C:\Users\kt841\Documents\SocialMedia\venv\Lib\site-packages\django\views\decorators\csrf.py", line 56, in wrapper_view
    return view_func(*args, **kwargs)
           ^^^^^^^^^^^^^^^^^^^^^^^^^^
  File "C:\Users\kt841\Documents\SocialMedia\venv\Lib\site-packages\django\views\generic\base.py", line 104, in view
    return self.dispatch(request, *args, **kwargs)
           ^^^^^^^^^^^^^^^^^^^^^^^^^^^^^^^^^^^^^^^
  File "C:\Users\kt841\Documents\SocialMedia\venv\Lib\site-packages\rest_framework\views.py", line 509, in dispatch
    response = self.handle_exception(exc)
               ^^^^^^^^^^^^^^^^^^^^^^^^^^
  File "C:\Users\kt841\Documents\SocialMedia\venv\Lib\site-packages\rest_framework\views.py", line 469, in handle_exception
    self.raise_uncaught_exception(exc)
  File "C:\Users\kt841\Documents\SocialMedia\venv\Lib\site-packages\rest_framework\views.py", line 480, in raise_uncaught_exception
    raise exc
  File "C:\Users\kt841\Documents\SocialMedia\venv\Lib\site-packages\rest_framework\views.py", line 506, in dispatch
    response = handler(request, *args, **kwargs)
               ^^^^^^^^^^^^^^^^^^^^^^^^^^^^^^^^^
  File "C:\Users\kt841\Documents\SocialMedia\social_media\post\views.py", line 160, in post
    comment = Comment(user=user_id, post=post_id, text=text)
              ^^^^^^^^^^^^^^^^^^^^^^^^^^^^^^^^^^^^^^^^^^^^^^
  File "C:\Users\kt841\Documents\SocialMedia\venv\Lib\site-packages\django\db\models\base.py", line 543, in __init__
    _setattr(self, field.name, rel_obj)
  File "C:\Users\kt841\Documents\SocialMedia\venv\Lib\site-packages\django\db\models\fields\related_descriptors.py", line 266, in __set__
    raise ValueError(
ValueError: Cannot assign "25": "Comment.user" must be a "User" instance.
"POST /post/comment/ HTTP/1.1" 500 103512
C:\Users\kt841\Documents\SocialMedia\social_media\post\views.py changed, reloading.
Watching for file changes with StatReloader
C:\Users\kt841\Documents\SocialMedia\social_media\post\views.py changed, reloading.
Watching for file changes with StatReloader
Internal Server Error: /post/comment/
Traceback (most recent call last):
  File "C:\Users\kt841\Documents\SocialMedia\venv\Lib\site-packages\django\core\handlers\exception.py", line 55, in inner
    response = get_response(request)
               ^^^^^^^^^^^^^^^^^^^^^
  File "C:\Users\kt841\Documents\SocialMedia\venv\Lib\site-packages\django\core\handlers\base.py", line 197, in _get_response
    response = wrapped_callback(request, *callback_args, **callback_kwargs)
               ^^^^^^^^^^^^^^^^^^^^^^^^^^^^^^^^^^^^^^^^^^^^^^^^^^^^^^^^^^^^
  File "C:\Users\kt841\Documents\SocialMedia\venv\Lib\site-packages\django\views\decorators\csrf.py", line 56, in wrapper_view
    return view_func(*args, **kwargs)
           ^^^^^^^^^^^^^^^^^^^^^^^^^^
  File "C:\Users\kt841\Documents\SocialMedia\venv\Lib\site-packages\django\views\generic\base.py", line 104, in view
    return self.dispatch(request, *args, **kwargs)
           ^^^^^^^^^^^^^^^^^^^^^^^^^^^^^^^^^^^^^^^
  File "C:\Users\kt841\Documents\SocialMedia\venv\Lib\site-packages\rest_framework\views.py", line 509, in dispatch
    response = self.handle_exception(exc)
               ^^^^^^^^^^^^^^^^^^^^^^^^^^
  File "C:\Users\kt841\Documents\SocialMedia\venv\Lib\site-packages\rest_framework\views.py", line 469, in handle_exception
    self.raise_uncaught_exception(exc)
  File "C:\Users\kt841\Documents\SocialMedia\venv\Lib\site-packages\rest_framework\views.py", line 480, in raise_uncaught_exception
    raise exc
  File "C:\Users\kt841\Documents\SocialMedia\venv\Lib\site-packages\rest_framework\views.py", line 506, in dispatch
    response = handler(request, *args, **kwargs)
               ^^^^^^^^^^^^^^^^^^^^^^^^^^^^^^^^^
  File "C:\Users\kt841\Documents\SocialMedia\social_media\post\views.py", line 160, in post
    comment = Comment(User=user_id, Post=post_id, text=text)
              ^^^^^^^^^^^^^^^^^^^^^^^^^^^^^^^^^^^^^^^^^^^^^^
  File "C:\Users\kt841\Documents\SocialMedia\venv\Lib\site-packages\django\db\models\base.py", line 567, in __init__
    raise TypeError(
TypeError: Comment() got unexpected keyword arguments: 'User', 'Post'
"POST /post/comment/ HTTP/1.1" 500 99824
Internal Server Error: /post/comment/
Traceback (most recent call last):
  File "C:\Users\kt841\Documents\SocialMedia\venv\Lib\site-packages\django\core\handlers\exception.py", line 55, in inner
    response = get_response(request)
               ^^^^^^^^^^^^^^^^^^^^^
  File "C:\Users\kt841\Documents\SocialMedia\venv\Lib\site-packages\django\core\handlers\base.py", line 197, in _get_response
    response = wrapped_callback(request, *callback_args, **callback_kwargs)
               ^^^^^^^^^^^^^^^^^^^^^^^^^^^^^^^^^^^^^^^^^^^^^^^^^^^^^^^^^^^^
  File "C:\Users\kt841\Documents\SocialMedia\venv\Lib\site-packages\django\views\decorators\csrf.py", line 56, in wrapper_view
    return view_func(*args, **kwargs)
           ^^^^^^^^^^^^^^^^^^^^^^^^^^
  File "C:\Users\kt841\Documents\SocialMedia\venv\Lib\site-packages\django\views\generic\base.py", line 104, in view
    return self.dispatch(request, *args, **kwargs)
           ^^^^^^^^^^^^^^^^^^^^^^^^^^^^^^^^^^^^^^^
  File "C:\Users\kt841\Documents\SocialMedia\venv\Lib\site-packages\rest_framework\views.py", line 509, in dispatch
    response = self.handle_exception(exc)
               ^^^^^^^^^^^^^^^^^^^^^^^^^^
  File "C:\Users\kt841\Documents\SocialMedia\venv\Lib\site-packages\rest_framework\views.py", line 469, in handle_exception
    self.raise_uncaught_exception(exc)
  File "C:\Users\kt841\Documents\SocialMedia\venv\Lib\site-packages\rest_framework\views.py", line 480, in raise_uncaught_exception
    raise exc
  File "C:\Users\kt841\Documents\SocialMedia\venv\Lib\site-packages\rest_framework\views.py", line 506, in dispatch
    response = handler(request, *args, **kwargs)
               ^^^^^^^^^^^^^^^^^^^^^^^^^^^^^^^^^
  File "C:\Users\kt841\Documents\SocialMedia\social_media\post\views.py", line 160, in post
    comment = Comment(User=user_id, Post=post_id, text=text)
              ^^^^^^^^^^^^^^^^^^^^^^^^^^^^^^^^^^^^^^^^^^^^^^
  File "C:\Users\kt841\Documents\SocialMedia\venv\Lib\site-packages\django\db\models\base.py", line 567, in __init__
    raise TypeError(
TypeError: Comment() got unexpected keyword arguments: 'User', 'Post'
"POST /post/comment/ HTTP/1.1" 500 99822
Internal Server Error: /post/comment/
Traceback (most recent call last):
  File "C:\Users\kt841\Documents\SocialMedia\venv\Lib\site-packages\django\core\handlers\exception.py", line 55, in inner
    response = get_response(request)
               ^^^^^^^^^^^^^^^^^^^^^
  File "C:\Users\kt841\Documents\SocialMedia\venv\Lib\site-packages\django\core\handlers\base.py", line 197, in _get_response
    response = wrapped_callback(request, *callback_args, **callback_kwargs)
               ^^^^^^^^^^^^^^^^^^^^^^^^^^^^^^^^^^^^^^^^^^^^^^^^^^^^^^^^^^^^
  File "C:\Users\kt841\Documents\SocialMedia\venv\Lib\site-packages\django\views\decorators\csrf.py", line 56, in wrapper_view
    return view_func(*args, **kwargs)
           ^^^^^^^^^^^^^^^^^^^^^^^^^^
  File "C:\Users\kt841\Documents\SocialMedia\venv\Lib\site-packages\django\views\generic\base.py", line 104, in view
    return self.dispatch(request, *args, **kwargs)
           ^^^^^^^^^^^^^^^^^^^^^^^^^^^^^^^^^^^^^^^
  File "C:\Users\kt841\Documents\SocialMedia\venv\Lib\site-packages\rest_framework\views.py", line 509, in dispatch
    response = self.handle_exception(exc)
               ^^^^^^^^^^^^^^^^^^^^^^^^^^
  File "C:\Users\kt841\Documents\SocialMedia\venv\Lib\site-packages\rest_framework\views.py", line 469, in handle_exception
    self.raise_uncaught_exception(exc)
  File "C:\Users\kt841\Documents\SocialMedia\venv\Lib\site-packages\rest_framework\views.py", line 480, in raise_uncaught_exception
    raise exc
  File "C:\Users\kt841\Documents\SocialMedia\venv\Lib\site-packages\rest_framework\views.py", line 506, in dispatch
    response = handler(request, *args, **kwargs)
               ^^^^^^^^^^^^^^^^^^^^^^^^^^^^^^^^^
  File "C:\Users\kt841\Documents\SocialMedia\social_media\post\views.py", line 160, in post
    comment = Comment(User=user_id, Post=post_id, text=text)
              ^^^^^^^^^^^^^^^^^^^^^^^^^^^^^^^^^^^^^^^^^^^^^^
  File "C:\Users\kt841\Documents\SocialMedia\venv\Lib\site-packages\django\db\models\base.py", line 567, in __init__
    raise TypeError(
TypeError: Comment() got unexpected keyword arguments: 'User', 'Post'
"POST /post/comment/ HTTP/1.1" 500 99822
C:\Users\kt841\Documents\SocialMedia\social_media\post\views.py changed, reloading.
Watching for file changes with StatReloader
C:\Users\kt841\Documents\SocialMedia\social_media\post\views.py changed, reloading.
Watching for file changes with StatReloader
Unauthorized: /post/comment/
"POST /post/comment/ HTTP/1.1" 401 183
"POST /api/token/refresh/ HTTP/1.1" 200 242
"POST /post/comment/ HTTP/1.1" 200 201
"GET /post/comment/ HTTP/1.1" 200 151
"GET /post/comment/ HTTP/1.1" 200 151
"POST /post/comment/ HTTP/1.1" 200 211
"GET /post/comment/ HTTP/1.1" 200 301
Watching for file changes with StatReloader
